Workbook

Sheet How to use
A1: Aurora Cycle Count Schedule
A2: A SKUs are counted weekly, B every 2 weeks, and C every 4 weeks (monthly). Counting days are Tuesday to Friday.
A4: Each week
A5: 1. In the Dashboard, open Cycle counts, pick Aurora, and download the Velocity classes table (CSV button, file velocity-Aurora.csv).
A6: 2. On the Velocity tab, clear the blue columns A–G (rows 2 and below), then paste the CSV in at cell A2, without its header row. Leave the grey columns alone; they're formulas.
A7: 3. To pin a SKU to a class, type A, B, C or D in the yellow Override column. Overrides are kept as long as the rows stay in the same order, so re-check them after pasting.
A8: 4. Check the Calendar tab: counts per day against capacity. Red cells are days over capacity.
A9: 5. On the Daily Count Sheet tab, pick a date in cell B3 and print. System quantity isn't shown (blind count).
A11: Classes
A12: The Dashboard's classes map to A/B/C: Fast = A, Medium = B, Slow = C. Dormant SKUs (stock on hand, no movement in 90 days) are D.
A13: D SKUs are counted once a year by default. To leave them off, set 'Schedule D (dormant) SKUs' to No on the Settings tab.
A14: The Class column in the Dashboard CSV comes through as 0/1/2/3 (Fast/Medium/Slow/Dormant). Words (Fast, Slow…) and letters (A, B, C) also work.
... A25: Example of the pasted format (one row of velocity-Aurora.csv)
A26: SKU | B26: Product | C26: Transactions | D26: Cumulative % | E26: Class | F26: Last counted | G26: On hand
A27: EP-1001-5G | B27: Epoxy Primer Part A, 5 gal | C27: 42 | D27: 12.4 | E27: 0 | F27: 2026-09-29 | G27: 18
A28: (Example only. Don't paste this row: it's here to show the column order.)

Sheet Settings
A1: Settings
A3: Location | B3: Aurora | C3: Label only.
A4: Schedule start (a Tuesday) | B4: 46315 | C4: Week 1 starts here. Must be a Tuesday. | D4: =IF(WEEKDAY(B4)=3,"","⚠ Not a Tuesday: counting days will be off")
A5: Daily capacity (SKUs per day) | B5: 50 | C5: Confirmed range is 40–60 SKUs a day.
A6: Schedule D (dormant) SKUs | B6: Yes | C6: Yes = count D SKUs on the D cadence below. No = leave them off.
A8: Class | B8: Dashboard class | C8: Cadence (weeks) | D8: Counting days per cycle | E8: SKUs | F8: SKUs per day | G8: Counts per 4 weeks
A9: A | B9: Fast | C9: 1 | D9: =C9*4 -> 4 | E9: =COUNTIF(Velocity!$I$2:$I$3001,A9) -> 0 | F9: =IF(OR(A9<>"D",$B$6="Yes"),E9/D9,0) -> 0 | G9: =IF(OR(A9<>"D",$B$6="Yes"),E9*4/C9,0) -> 0
A10: B | B10: Medium | C10: 2 | D10: =C10*4 -> 8 | E10: =COUNTIF(Velocity!$I$2:$I$3001,A10) -> 0 | F10: =IF(OR(A10<>"D",$B$6="Yes"),E10/D10,0) -> 0 | G10: =IF(OR(A10<>"D",$B$6="Yes"),E10*4/C10,0) -> 0
A11: C | B11: Slow | C11: 4 | D11: =C11*4 -> 16 | E11: =COUNTIF(Velocity!$I$2:$I$3001,A11) -> 0 | F11: =IF(OR(A11<>"D",$B$6="Yes"),E11/D11,0) -> 0 | G11: =IF(OR(A11<>"D",$B$6="Yes"),E11*4/C11,0) -> 0
A12: D | B12: Dormant | C12: 52 | D12: =C12*4 -> 208 | E12: =COUNTIF(Velocity!$I$2:$I$3001,A12) -> 0 | F12: =IF(OR(A12<>"D",$B$6="Yes"),E12/D12,0) -> 0 | G12: =IF(OR(A12<>"D",$B$6="Yes"),E12*4/C12,0) -> 0
A13: Total | E13: =SUM(E9:E12) -> 0 | F13: =SUM(F9:F12) -> 0 | G13: =SUM(G9:G12) -> 0
A14: Capacity check | B14: =IF(E13=0,"Paste the velocity CSV on the Velocity tab",IF(F13<=$B$5,"OK: "&TEXT(F13,"0.0")&" SKUs a day needed, capacity "&$B$5,"Over capacity by "&TEXT(F13-$B$5,"0.0")&" SKUs a day. Options: raise capacity, move some A SKUs to B (Override column), or lengthen the C cadence")) -> Paste the velocity CSV on the Velocity tab
A16: Cadence and capacity are editable. 'SKUs per day' is the average load: SKUs ÷ (cadence weeks × 4 counting days).

Sheet Velocity
A1: SKU | B1: Product | C1: Transactions | D1: Cumulative % | E1: Class | F1: Last counted | G1: On hand | H1: Override (A/B/C/D) | I1: ABC class | J1: Cadence (weeks) | K1: # in class | L1: Count day | M1: Cycle week | N1: First count | O1: Next count | P1: _slot | Q1: _day | R1: _week | S1: _due | T1: _seq
I2: =IF(A2="","",IF(H2<>"",UPPER(TRIM(H2)),IFERROR(CHOOSE(VALUE(E2)+1,"A","B","C","D"),IF(OR(LEFT(UPPER(TRIM(E2)),1)="F",UPPER(TRIM(E2))="A"),"A",IF(OR(LEFT(UPPER(TRIM(E2)),1)="M",UPPER(TRIM(E2))="B"),"B",IF(OR(LEFT(UPPER(TRIM(E2)),2)="SL",UPPER(TRIM(E2))="C"),"C",IF(OR(LEFT(UPPER(TRIM(E2)),1)="D",UPPER(TRIM(E2))="D"),"D",""))))))) | J2: =IF(I2="","",IF(AND(I2="D",Settings!$B$6<>"Yes"),"",IFERROR(INDEX(Settings!$C$9:$C$12,MATCH(I2,Settings!$A$9:$A$12,0)),""))) | K2: =IF(J2="","",COUNTIF($I$2:I2,I2)) | L2: =IF(J2="","",CHOOSE(Q2+1,"Tue","Wed","Thu","Fri")) | M2: =IF(J2="","",IF(J2=1,"Every week",R2+1&" of "&J2)) | N2: =IF(J2="","",Settings!$B$4+R2*7+Q2) | O2: =IF(J2="","",N2+MAX(0,ROUNDUP((TODAY()-N2)/(J2*7),0))*J2*7) | P2: =IF(J2="","",MOD(K2-1,J2*4)) | Q2: =IF(J2="","",MOD(P2,4)) | R2: =IF(J2="","",INT(P2/4)) | S2: =IF(J2="","",IF(AND('Daily Count Sheet'!$H$3=Q2,MOD('Daily Count Sheet'!$I$3,J2)=R2),1,"")) | T2: =IF(S2=1,COUNTIF($S$2:S2,1),"")
I3: =IF(A3="","",IF(H3<>"",UPPER(TRIM(H3)),IFERROR(CHOOSE(VALUE(E3)+1,"A","B","C","D"),IF(OR(LEFT(UPPER(TRIM(E3)),1)="F",UPPER(TRIM(E3))="A"),"A",IF(OR(LEFT(UPPER(TRIM(E3)),1)="M",UPPER(TRIM(E3))="B"),"B",IF(OR(LEFT(UPPER(TRIM(E3)),2)="SL",UPPER(TRIM(E3))="C"),"C",IF(OR(LEFT(UPPER(TRIM(E3)),1)="D",UPPER(TRIM(E3))="D"),"D",""))))))) | J3: =IF(I3="","",IF(AND(I3="D",Settings!$B$6<>"Yes"),"",IFERROR(INDEX(Settings!$C$9:$C$12,MATCH(I3,Settings!$A$9:$A$12,0)),""))) | K3: =IF(J3="","",COUNTIF($I$2:I3,I3)) | L3: =IF(J3="","",CHOOSE(Q3+1,"Tue","Wed","Thu","Fri")) | M3: =IF(J3="","",IF(J3=1,"Every week",R3+1&" of "&J3)) | N3: =IF(J3="","",Settings!$B$4+R3*7+Q3) | O3: =IF(J3="","",N3+MAX(0,ROUNDUP((TODAY()-N3)/(J3*7),0))*J3*7) | P3: =IF(J3="","",MOD(K3-1,J3*4)) | Q3: =IF(J3="","",MOD(P3,4)) | R3: =IF(J3="","",INT(P3/4)) | S3: =IF(J3="","",IF(AND('Daily Count Sheet'!$H$3=Q3,MOD('Daily Count Sheet'!$I$3,J3)=R3),1,"")) | T3: =IF(S3=1,COUNTIF($S$2:S3,1),"")
I4: =IF(A4="","",IF(H4<>"",UPPER(TRIM(H4)),IFERROR(CHOOSE(VALUE(E4)+1,"A","B","C","D"),IF(OR(LEFT(UPPER(TRIM(E4)),1)="F",UPPER(TRIM(E4))="A"),"A",IF(OR(LEFT(UPPER(TRIM(E4)),1)="M",UPPER(TRIM(E4))="B"),"B",IF(OR(LEFT(UPPER(TRIM(E4)),2)="SL",UPPER(TRIM(E4))="C"),"C",IF(OR(LEFT(UPPER(TRIM(E4)),1)="D",UPPER(TRIM(E4))="D"),"D",""))))))) | J4: =IF(I4="","",IF(AND(I4="D",Settings!$B$6<>"Yes"),"",IFERROR(INDEX(Settings!$C$9:$C$12,MATCH(I4,Settings!$A$9:$A$12,0)),""))) | K4: =IF(J4="","",COUNTIF($I$2:I4,I4)) | L4: =IF(J4="","",CHOOSE(Q4+1,"Tue","Wed","Thu","Fri")) | M4: =IF(J4="","",IF(J4=1,"Every week",R4+1&" of "&J4)) | N4: =IF(J4="","",Settings!$B$4+R4*7+Q4) | O4: =IF(J4="","",N4+MAX(0,ROUNDUP((TODAY()-N4)/(J4*7),0))*J4*7) | P4: =IF(J4="","",MOD(K4-1,J4*4)) | Q4: =IF(J4="","",MOD(P4,4)) | R4: =IF(J4="","",INT(P4/4)) | S4: =IF(J4="","",IF(AND('Daily Count Sheet'!$H$3=Q4,MOD('Daily Count Sheet'!$I$3,J4)=R4),1,"")) | T4: =IF(S4=1,COUNTIF($S$2:S4,1),"")
I5: =IF(A5="","",IF(H5<>"",UPPER(TRIM(H5)),IFERROR(CHOOSE(VALUE(E5)+1,"A","B","C","D"),IF(OR(LEFT(UPPER(TRIM(E5)),1)="F",UPPER(TRIM(E5))="A"),"A",IF(OR(LEFT(UPPER(TRIM(E5)),1)="M",UPPER(TRIM(E5))="B"),"B",IF(OR(LEFT(UPPER(TRIM(E5)),2)="SL",UPPER(TRIM(E5))="C"),"C",IF(OR(LEFT(UPPER(TRIM(E5)),1)="D",UPPER(TRIM(E5))="D"),"D",""))))))) | J5: =IF(I5="","",IF(AND(I5="D",Settings!$B$6<>"Yes"),"",IFERROR(INDEX(Settings!$C$9:$C$12,MATCH(I5,Settings!$A$9:$A$12,0)),""))) | K5: =IF(J5="","",COUNTIF($I$2:I5,I5)) | L5: =IF(J5="","",CHOOSE(Q5+1,"Tue","Wed","Thu","Fri")) | M5: =IF(J5="","",IF(J5=1,"Every week",R5+1&" of "&J5)) | N5: =IF(J5="","",Settings!$B$4+R5*7+Q5) | O5: =IF(J5="","",N5+MAX(0,ROUNDUP((TODAY()-N5)/(J5*7),0))*J5*7) | P5: =IF(J5="","",MOD(K5-1,J5*4)) | Q5: =IF(J5="","",MOD(P5,4)) | R5: =IF(J5="","",INT(P5/4)) | S5: =IF(J5="","",IF(AND('Daily Count Sheet'!$H$3=Q5,MOD('Daily Count Sheet'!$I$3,J5)=R5),1,"")) | T5: =IF(S5=1,COUNTIF($S$2:S5,1),"")
I6: =IF(A6="","",IF(H6<>"",UPPER(TRIM(H6)),IFERROR(CHOOSE(VALUE(E6)+1,"A","B","C","D"),IF(OR(LEFT(UPPER(TRIM(E6)),1)="F",UPPER(TRIM(E6))="A"),"A",IF(OR(LEFT(UPPER(TRIM(E6)),1)="M",UPPER(TRIM(E6))="B"),"B",IF(OR(LEFT(UPPER(TRIM(E6)),2)="SL",UPPER(TRIM(E6))="C"),"C",IF(OR(LEFT(UPPER(TRIM(E6)),1)="D",UPPER(TRIM(E6))="D"),"D",""))))))) | J6: =IF(I6="","",IF(AND(I6="D",Settings!$B$6<>"Yes"),"",IFERROR(INDEX(Settings!$C$9:$C$12,MATCH(I6,Settings!$A$9:$A$12,0)),""))) | K6: =IF(J6="","",COUNTIF($I$2:I6,I6)) | L6: =IF(J6="","",CHOOSE(Q6+1,"Tue","Wed","Thu","Fri")) | M6: =IF(J6="","",IF(J6=1,"Every week",R6+1&" of "&J6)) | N6: =IF(J6="","",Settings!$B$4+R6*7+Q6) | O6: =IF(J6="","",N6+MAX(0,ROUNDUP((TODAY()-N6)/(J6*7),0))*J6*7) | P6: =IF(J6="","",MOD(K6-1,J6*4)) | Q6: =IF(J6="","",MOD(P6,4)) | R6: =IF(J6="","",INT(P6/4)) | S6: =IF(J6="","",IF(AND('Daily Count Sheet'!$H$3=Q6,MOD('Daily Count Sheet'!$I$3,J6)=R6),1,"")) | T6: =IF(S6=1,COUNTIF($S$2:S6,1),"")
I7: =IF(A7="","",IF(H7<>"",UPPER(TRIM(H7)),IFERROR(CHOOSE(VALUE(E7)+1,"A","B","C","D"),IF(OR(LEFT(UPPER(TRIM(E7)),1)="F",UPPER(TRIM(E7))="A"),"A",IF(OR(LEFT(UPPER(TRIM(E7)),1)="M",UPPER(TRIM(E7))="B"),"B",IF(OR(LEFT(UPPER(TRIM(E7)),2)="SL",UPPER(TRIM(E7))="C"),"C",IF(OR(LEFT(UPPER(TRIM(E7)),1)="D",UPPER(TRIM(E7))="D"),"D",""))))))) | J7: =IF(I7="","",IF(AND(I7="D",Settings!$B$6<>"Yes"),"",IFERROR(INDEX(Settings!$C$9:$C$12,MATCH(I7,Settings!$A$9:$A$12,0)),""))) | K7: =IF(J7="","",COUNTIF($I$2:I7,I7)) | L7: =IF(J7="","",CHOOSE(Q7+1,"Tue","Wed","Thu","Fri")) | M7: =IF(J7="","",IF(J7=1,"Every week",R7+1&" of "&J7)) | N7: =IF(J7="","",Settings!$B$4+R7*7+Q7) | O7: =IF(J7="","",N7+MAX(0,ROUNDUP((TODAY()-N7)/(J7*7),0))*J7*7) | P7: =IF(J7="","",MOD(K7-1,J7*4)) | Q7: =IF(J7="","",MOD(P7,4)) | R7: =IF(J7="","",INT(P7/4)) | S7: =IF(J7="","",IF(AND('Daily Count Sheet'!$H$3=Q7,MOD('Daily Count Sheet'!$I$3,J7)=R7),1,"")) | T7: =IF(S7=1,COUNTIF($S$2:S7,1),"")
I8: =IF(A8="","",IF(H8<>"",UPPER(TRIM(H8)),IFERROR(CHOOSE(VALUE(E8)+1,"A","B","C","D"),IF(OR(LEFT(UPPER(TRIM(E8)),1)="F",UPPER(TRIM(E8))="A"),"A",IF(OR(LEFT(UPPER(TRIM(E8)),1)="M",UPPER(TRIM(E8))="B"),"B",IF(OR(LEFT(UPPER(TRIM(E8)),2)="SL",UPPER(TRIM(E8))="C"),"C",IF(OR(LEFT(UPPER(TRIM(E8)),1)="D",UPPER(TRIM(E8))="D"),"D",""))))))) | J8: =IF(I8="","",IF(AND(I8="D",Settings!$B$6<>"Yes"),"",IFERROR(INDEX(Settings!$C$9:$C$12,MATCH(I8,Settings!$A$9:$A$12,0)),""))) | K8: =IF(J8="","",COUNTIF($I$2:I8,I8)) | L8: =IF(J8="","",CHOOSE(Q8+1,"Tue","Wed","Thu","Fri")) | M8: =IF(J8="","",IF(J8=1,"Every week",R8+1&" of "&J8)) | N8: =IF(J8="","",Settings!$B$4+R8*7+Q8) | O8: =IF(J8="","",N8+MAX(0,ROUNDUP((TODAY()-N8)/(J8*7),0))*J8*7) | P8: =IF(J8="","",MOD(K8-1,J8*4)) | Q8: =IF(J8="","",MOD(P8,4)) | R8: =IF(J8="","",INT(P8/4)) | S8: =IF(J8="","",IF(AND('Daily Count Sheet'!$H$3=Q8,MOD('Daily Count Sheet'!$I$3,J8)=R8),1,"")) | T8: =IF(S8=1,COUNTIF($S$2:S8,1),"")
I9: =IF(A9="","",IF(H9<>"",UPPER(TRIM(H9)),IFERROR(CHOOSE(VALUE(E9)+1,"A","B","C","D"),IF(OR(LEFT(UPPER(TRIM(E9)),1)="F",UPPER(TRIM(E9))="A"),"A",IF(OR(LEFT(UPPER(TRIM(E9)),1)="M",UPPER(TRIM(E9))="B"),"B",IF(OR(LEFT(UPPER(TRIM(E9)),2)="SL",UPPER(TRIM(E9))="C"),"C",IF(OR(LEFT(UPPER(TRIM(E9)),1)="D",UPPER(TRIM(E9))="D"),"D",""))))))) | J9: =IF(I9="","",IF(AND(I9="D",Settings!$B$6<>"Yes"),"",IFERROR(INDEX(Settings!$C$9:$C$12,MATCH(I9,Settings!$A$9:$A$12,0)),""))) | K9: =IF(J9="","",COUNTIF($I$2:I9,I9)) | L9: =IF(J9="","",CHOOSE(Q9+1,"Tue","Wed","Thu","Fri")) | M9: =IF(J9="","",IF(J9=1,"Every week",R9+1&" of "&J9)) | N9: =IF(J9="","",Settings!$B$4+R9*7+Q9) | O9: =IF(J9="","",N9+MAX(0,ROUNDUP((TODAY()-N9)/(J9*7),0))*J9*7) | P9: =IF(J9="","",MOD(K9-1,J9*4)) | Q9: =IF(J9="","",MOD(P9,4)) | R9: =IF(J9="","",INT(P9/4)) | S9: =IF(J9="","",IF(AND('Daily Count Sheet'!$H$3=Q9,MOD('Daily Count Sheet'!$I$3,J9)=R9),1,"")) | T9: =IF(S9=1,COUNTIF($S$2:S9,1),"")
I10: =IF(A10="","",IF(H10<>"",UPPER(TRIM(H10)),IFERROR(CHOOSE(VALUE(E10)+1,"A","B","C","D"),IF(OR(LEFT(UPPER(TRIM(E10)),1)="F",UPPER(TRIM(E10))="A"),"A",IF(OR(LEFT(UPPER(TRIM(E10)),1)="M",UPPER(TRIM(E10))="B"),"B",IF(OR(LEFT(UPPER(TRIM(E10)),2)="SL",UPPER(TRIM(E10))="C"),"C",IF(OR(LEFT(UPPER(TRIM(E10)),1)="D",UPPER(TRIM(E10))="D"),"D",""))))))) | J10: =IF(I10="","",IF(AND(I10="D",Settings!$B$6<>"Yes"),"",IFERROR(INDEX(Settings!$C$9:$C$12,MATCH(I10,Settings!$A$9:$A$12,0)),""))) | K10: =IF(J10="","",COUNTIF($I$2:I10,I10)) | L10: =IF(J10="","",CHOOSE(Q10+1,"Tue","Wed","Thu","Fri")) | M10: =IF(J10="","",IF(J10=1,"Every week",R10+1&" of "&J10)) | N10: =IF(J10="","",Settings!$B$4+R10*7+Q10) | O10: =IF(J10="","",N10+MAX(0,ROUNDUP((TODAY()-N10)/(J10*7),0))*J10*7) | P10: =IF(J10="","",MOD(K10-1,J10*4)) | Q10: =IF(J10="","",MOD(P10,4)) | R10: =IF(J10="","",INT(P10/4)) | S10: =IF(J10="","",IF(AND('Daily Count Sheet'!$H$3=Q10,MOD('Daily Count Sheet'!$I$3,J10)=R10),1,"")) | T10: =IF(S10=1,COUNTIF($S$2:S10,1),"")
I11: =IF(A11="","",IF(H11<>"",UPPER(TRIM(H11)),IFERROR(CHOOSE(VALUE(E11)+1,"A","B","C","D"),IF(OR(LEFT(UPPER(TRIM(E11)),1)="F",UPPER(TRIM(E11))="A"),"A",IF(OR(LEFT(UPPER(TRIM(E11)),1)="M",UPPER(TRIM(E11))="B"),"B",IF(OR(LEFT(UPPER(TRIM(E11)),2)="SL",UPPER(TRIM(E11))="C"),"C",IF(OR(LEFT(UPPER(TRIM(E11)),1)="D",UPPER(TRIM(E11))="D"),"D",""))))))) | J11: =IF(I11="","",IF(AND(I11="D",Settings!$B$6<>"Yes"),"",IFERROR(INDEX(Settings!$C$9:$C$12,MATCH(I11,Settings!$A$9:$A$12,0)),""))) | K11: =IF(J11="","",COUNTIF($I$2:I11,I11)) | L11: =IF(J11="","",CHOOSE(Q11+1,"Tue","Wed","Thu","Fri")) | M11: =IF(J11="","",IF(J11=1,"Every week",R11+1&" of "&J11)) | N11: =IF(J11="","",Settings!$B$4+R11*7+Q11) | O11: =IF(J11="","",N11+MAX(0,ROUNDUP((TODAY()-N11)/(J11*7),0))*J11*7) | P11: =IF(J11="","",MOD(K11-1,J11*4)) | Q11: =IF(J11="","",MOD(P11,4)) | R11: =IF(J11="","",INT(P11/4)) | S11: =IF(J11="","",IF(AND('Daily Count Sheet'!$H$3=Q11,MOD('Daily Count Sheet'!$I$3,J11)=R11),1,"")) | T11: =IF(S11=1,COUNTIF($S$2:S11,1),"")
I12: =IF(A12="","",IF(H12<>"",UPPER(TRIM(H12)),IFERROR(CHOOSE(VALUE(E12)+1,"A","B","C","D"),IF(OR(LEFT(UPPER(TRIM(E12)),1)="F",UPPER(TRIM(E12))="A"),"A",IF(OR(LEFT(UPPER(TRIM(E12)),1)="M",UPPER(TRIM(E12))="B"),"B",IF(OR(LEFT(UPPER(TRIM(E12)),2)="SL",UPPER(TRIM(E12))="C"),"C",IF(OR(LEFT(UPPER(TRIM(E12)),1)="D",UPPER(TRIM(E12))="D"),"D",""))))))) | J12: =IF(I12="","",IF(AND(I12="D",Settings!$B$6<>"Yes"),"",IFERROR(INDEX(Settings!$C$9:$C$12,MATCH(I12,Settings!$A$9:$A$12,0)),""))) | K12: =IF(J12="","",COUNTIF($I$2:I12,I12)) | L12: =IF(J12="","",CHOOSE(Q12+1,"Tue","Wed","Thu","Fri")) | M12: =IF(J12="","",IF(J12=1,"Every week",R12+1&" of "&J12)) | N12: =IF(J12="","",Settings!$B$4+R12*7+Q12) | O12: =IF(J12="","",N12+MAX(0,ROUNDUP((TODAY()-N12)/(J12*7),0))*J12*7) | P12: =IF(J12="","",MOD(K12-1,J12*4)) | Q12: =IF(J12="","",MOD(P12,4)) | R12: =IF(J12="","",INT(P12/4)) | S12: =IF(J12="","",IF(AND('Daily Count Sheet'!$H$3=Q12,MOD('Daily Count Sheet'!$I$3,J12)=R12),1,"")) | T12: =IF(S12=1,COUNTIF($S$2:S12,1),"")
I13: =IF(A13="","",IF(H13<>"",UPPER(TRIM(H13)),IFERROR(CHOOSE(VALUE(E13)+1,"A","B","C","D"),IF(OR(LEFT(UPPER(TRIM(E13)),1)="F",UPPER(TRIM(E13))="A"),"A",IF(OR(LEFT(UPPER(TRIM(E13)),1)="M",UPPER(TRIM(E13))="B"),"B",IF(OR(LEFT(UPPER(TRIM(E13)),2)="SL",UPPER(TRIM(E13))="C"),"C",IF(OR(LEFT(UPPER(TRIM(E13)),1)="D",UPPER(TRIM(E13))="D"),"D",""))))))) | J13: =IF(I13="","",IF(AND(I13="D",Settings!$B$6<>"Yes"),"",IFERROR(INDEX(Settings!$C$9:$C$12,MATCH(I13,Settings!$A$9:$A$12,0)),""))) | K13: =IF(J13="","",COUNTIF($I$2:I13,I13)) | L13: =IF(J13="","",CHOOSE(Q13+1,"Tue","Wed","Thu","Fri")) | M13: =IF(J13="","",IF(J13=1,"Every week",R13+1&" of "&J13)) | N13: =IF(J13="","",Settings!$B$4+R13*7+Q13) | O13: =IF(J13="","",N13+MAX(0,ROUNDUP((TODAY()-N13)/(J13*7),0))*J13*7) | P13: =IF(J13="","",MOD(K13-1,J13*4)) | Q13: =IF(J13="","",MOD(P13,4)) | R13: =IF(J13="","",INT(P13/4)) | S13: =IF(J13="","",IF(AND('Daily Count Sheet'!$H$3=Q13,MOD('Daily Count Sheet'!$I$3,J13)=R13),1,"")) | T13: =IF(S13=1,COUNTIF($S$2:S13,1),"")
... I3001: =IF(A3001="","",IF(H3001<>"",UPPER(TRIM(H3001)),IFERROR(CHOOSE(VALUE(E3001)+1,"A","B","C","D"),IF(OR(LEFT(UPPER(TRIM(E3001)),1)="F",UPPER(TRIM(E3001))="A"),"A",IF(OR(LEFT(UPPER(TRIM(E3001)),1)="M",UPPER(TRIM(E3001))="B"),"B",IF(OR(LEFT(UPPER(TRIM(E3001)),2)="SL",UPPER(TRIM(E3001))="C"),"C",IF(OR(LEFT(UPPER(TRIM(E3001)),1)="D",UPPER(TRIM(E3001))="D"),"D",""))))))) | J3001: =IF(I3001="","",IF(AND(I3001="D",Settings!$B$6<>"Yes"),"",IFERROR(INDEX(Settings!$C$9:$C$12,MATCH(I3001,Settings!$A$9:$A$12,0)),""))) | K3001: =IF(J3001="","",COUNTIF($I$2:I3001,I3001)) | L3001: =IF(J3001="","",CHOOSE(Q3001+1,"Tue","Wed","Thu","Fri")) | M3001: =IF(J3001="","",IF(J3001=1,"Every week",R3001+1&" of "&J3001)) | N3001: =IF(J3001="","",Settings!$B$4+R3001*7+Q3001) | O3001: =IF(J3001="","",N3001+MAX(0,ROUNDUP((TODAY()-N3001)/(J3001*7),0))*J3001*7) | P3001: =IF(J3001="","",MOD(K3001-1,J3001*4)) | Q3001: =IF(J3001="","",MOD(P3001,4)) | R3001: =IF(J3001="","",INT(P3001/4)) | S3001: =IF(J3001="","",IF(AND('Daily Count Sheet'!$H$3=Q3001,MOD('Daily Count Sheet'!$I$3,J3001)=R3001),1,"")) | T3001: =IF(S3001=1,COUNTIF($S$2:S3001,1),"")

Sheet Calendar
A1: Count Calendar: Aurora
A2: ="13 weeks from "&TEXT(Settings!$B$4,"ddd m/d/yyyy")&". Capacity "&Settings!$B$5&" SKUs a day." -> 13 weeks from Tue 10/20/2026. Capacity 50 SKUs a day.
A4: Date | B4: Day | C4: Week | D4: A (weekly) | E4: B (2 weeks) | F4: C (4 weeks) | G4: D (dormant) | H4: Total | I4: Capacity | J4: Room left
A5: =Settings!$B$4+INT((5-5)/4)*7+MOD(5-5,4) -> 46315 | B5: =CHOOSE(MOD(5-5,4)+1,"Tue","Wed","Thu","Fri") -> Tue | C5: =INT((5-5)/4)+1 -> 1 | D5: =COUNTIFS(Velocity!$I$2:$I$3001,"A",Velocity!$Q$2:$Q$3001,MOD(5-5,4),Velocity!$R$2:$R$3001,MOD($C5-1,Settings!$C$9)) -> 0 | E5: =COUNTIFS(Velocity!$I$2:$I$3001,"B",Velocity!$Q$2:$Q$3001,MOD(5-5,4),Velocity!$R$2:$R$3001,MOD($C5-1,Settings!$C$10)) -> 0 | F5: =COUNTIFS(Velocity!$I$2:$I$3001,"C",Velocity!$Q$2:$Q$3001,MOD(5-5,4),Velocity!$R$2:$R$3001,MOD($C5-1,Settings!$C$11)) -> 0 | G5: =COUNTIFS(Velocity!$I$2:$I$3001,"D",Velocity!$Q$2:$Q$3001,MOD(5-5,4),Velocity!$R$2:$R$3001,MOD($C5-1,Settings!$C$12)) -> 0 | H5: =SUM(D5:G5) -> 0 | I5: =Settings!$B$5 -> 50 | J5: =I5-H5 -> 50
A6: =Settings!$B$4+INT((6-5)/4)*7+MOD(6-5,4) -> 46316 | B6: =CHOOSE(MOD(6-5,4)+1,"Tue","Wed","Thu","Fri") -> Wed | C6: =INT((6-5)/4)+1 -> 1 | D6: =COUNTIFS(Velocity!$I$2:$I$3001,"A",Velocity!$Q$2:$Q$3001,MOD(6-5,4),Velocity!$R$2:$R$3001,MOD($C6-1,Settings!$C$9)) -> 0 | E6: =COUNTIFS(Velocity!$I$2:$I$3001,"B",Velocity!$Q$2:$Q$3001,MOD(6-5,4),Velocity!$R$2:$R$3001,MOD($C6-1,Settings!$C$10)) -> 0 | F6: =COUNTIFS(Velocity!$I$2:$I$3001,"C",Velocity!$Q$2:$Q$3001,MOD(6-5,4),Velocity!$R$2:$R$3001,MOD($C6-1,Settings!$C$11)) -> 0 | G6: =COUNTIFS(Velocity!$I$2:$I$3001,"D",Velocity!$Q$2:$Q$3001,MOD(6-5,4),Velocity!$R$2:$R$3001,MOD($C6-1,Settings!$C$12)) -> 0 | H6: =SUM(D6:G6) -> 0 | I6: =Settings!$B$5 -> 50 | J6: =I6-H6 -> 50
A7: =Settings!$B$4+INT((7-5)/4)*7+MOD(7-5,4) -> 46317 | B7: =CHOOSE(MOD(7-5,4)+1,"Tue","Wed","Thu","Fri") -> Thu | C7: =INT((7-5)/4)+1 -> 1 | D7: =COUNTIFS(Velocity!$I$2:$I$3001,"A",Velocity!$Q$2:$Q$3001,MOD(7-5,4),Velocity!$R$2:$R$3001,MOD($C7-1,Settings!$C$9)) -> 0 | E7: =COUNTIFS(Velocity!$I$2:$I$3001,"B",Velocity!$Q$2:$Q$3001,MOD(7-5,4),Velocity!$R$2:$R$3001,MOD($C7-1,Settings!$C$10)) -> 0 | F7: =COUNTIFS(Velocity!$I$2:$I$3001,"C",Velocity!$Q$2:$Q$3001,MOD(7-5,4),Velocity!$R$2:$R$3001,MOD($C7-1,Settings!$C$11)) -> 0 | G7: =COUNTIFS(Velocity!$I$2:$I$3001,"D",Velocity!$Q$2:$Q$3001,MOD(7-5,4),Velocity!$R$2:$R$3001,MOD($C7-1,Settings!$C$12)) -> 0 | H7: =SUM(D7:G7) -> 0 | I7: =Settings!$B$5 -> 50 | J7: =I7-H7 -> 50
A8: =Settings!$B$4+INT((8-5)/4)*7+MOD(8-5,4) -> 46318 | B8: =CHOOSE(MOD(8-5,4)+1,"Tue","Wed","Thu","Fri") -> Fri | C8: =INT((8-5)/4)+1 -> 1 | D8: =COUNTIFS(Velocity!$I$2:$I$3001,"A",Velocity!$Q$2:$Q$3001,MOD(8-5,4),Velocity!$R$2:$R$3001,MOD($C8-1,Settings!$C$9)) -> 0 | E8: =COUNTIFS(Velocity!$I$2:$I$3001,"B",Velocity!$Q$2:$Q$3001,MOD(8-5,4),Velocity!$R$2:$R$3001,MOD($C8-1,Settings!$C$10)) -> 0 | F8: =COUNTIFS(Velocity!$I$2:$I$3001,"C",Velocity!$Q$2:$Q$3001,MOD(8-5,4),Velocity!$R$2:$R$3001,MOD($C8-1,Settings!$C$11)) -> 0 | G8: =COUNTIFS(Velocity!$I$2:$I$3001,"D",Velocity!$Q$2:$Q$3001,MOD(8-5,4),Velocity!$R$2:$R$3001,MOD($C8-1,Settings!$C$12)) -> 0 | H8: =SUM(D8:G8) -> 0 | I8: =Settings!$B$5 -> 50 | J8: =I8-H8 -> 50
A9: =Settings!$B$4+INT((9-5)/4)*7+MOD(9-5,4) -> 46322 | B9: =CHOOSE(MOD(9-5,4)+1,"Tue","Wed","Thu","Fri") -> Tue | C9: =INT((9-5)/4)+1 -> 2 | D9: =COUNTIFS(Velocity!$I$2:$I$3001,"A",Velocity!$Q$2:$Q$3001,MOD(9-5,4),Velocity!$R$2:$R$3001,MOD($C9-1,Settings!$C$9)) -> 0 | E9: =COUNTIFS(Velocity!$I$2:$I$3001,"B",Velocity!$Q$2:$Q$3001,MOD(9-5,4),Velocity!$R$2:$R$3001,MOD($C9-1,Settings!$C$10)) -> 0 | F9: =COUNTIFS(Velocity!$I$2:$I$3001,"C",Velocity!$Q$2:$Q$3001,MOD(9-5,4),Velocity!$R$2:$R$3001,MOD($C9-1,Settings!$C$11)) -> 0 | G9: =COUNTIFS(Velocity!$I$2:$I$3001,"D",Velocity!$Q$2:$Q$3001,MOD(9-5,4),Velocity!$R$2:$R$3001,MOD($C9-1,Settings!$C$12)) -> 0 | H9: =SUM(D9:G9) -> 0 | I9: =Settings!$B$5 -> 50 | J9: =I9-H9 -> 50
A10: =Settings!$B$4+INT((10-5)/4)*7+MOD(10-5,4) -> 46323 | B10: =CHOOSE(MOD(10-5,4)+1,"Tue","Wed","Thu","Fri") -> Wed | C10: =INT((10-5)/4)+1 -> 2 | D10: =COUNTIFS(Velocity!$I$2:$I$3001,"A",Velocity!$Q$2:$Q$3001,MOD(10-5,4),Velocity!$R$2:$R$3001,MOD($C10-1,Settings!$C$9)) -> 0 | E10: =COUNTIFS(Velocity!$I$2:$I$3001,"B",Velocity!$Q$2:$Q$3001,MOD(10-5,4),Velocity!$R$2:$R$3001,MOD($C10-1,Settings!$C$10)) -> 0 | F10: =COUNTIFS(Velocity!$I$2:$I$3001,"C",Velocity!$Q$2:$Q$3001,MOD(10-5,4),Velocity!$R$2:$R$3001,MOD($C10-1,Settings!$C$11)) -> 0 | G10: =COUNTIFS(Velocity!$I$2:$I$3001,"D",Velocity!$Q$2:$Q$3001,MOD(10-5,4),Velocity!$R$2:$R$3001,MOD($C10-1,Settings!$C$12)) -> 0 | H10: =SUM(D10:G10) -> 0 | I10: =Settings!$B$5 -> 50 | J10: =I10-H10 -> 50
A11: =Settings!$B$4+INT((11-5)/4)*7+MOD(11-5,4) -> 46324 | B11: =CHOOSE(MOD(11-5,4)+1,"Tue","Wed","Thu","Fri") -> Thu | C11: =INT((11-5)/4)+1 -> 2 | D11: =COUNTIFS(Velocity!$I$2:$I$3001,"A",Velocity!$Q$2:$Q$3001,MOD(11-5,4),Velocity!$R$2:$R$3001,MOD($C11-1,Settings!$C$9)) -> 0 | E11: =COUNTIFS(Velocity!$I$2:$I$3001,"B",Velocity!$Q$2:$Q$3001,MOD(11-5,4),Velocity!$R$2:$R$3001,MOD($C11-1,Settings!$C$10)) -> 0 | F11: =COUNTIFS(Velocity!$I$2:$I$3001,"C",Velocity!$Q$2:$Q$3001,MOD(11-5,4),Velocity!$R$2:$R$3001,MOD($C11-1,Settings!$C$11)) -> 0 | G11: =COUNTIFS(Velocity!$I$2:$I$3001,"D",Velocity!$Q$2:$Q$3001,MOD(11-5,4),Velocity!$R$2:$R$3001,MOD($C11-1,Settings!$C$12)) -> 0 | H11: =SUM(D11:G11) -> 0 | I11: =Settings!$B$5 -> 50 | J11: =I11-H11 -> 50
A12: =Settings!$B$4+INT((12-5)/4)*7+MOD(12-5,4) -> 46325 | B12: =CHOOSE(MOD(12-5,4)+1,"Tue","Wed","Thu","Fri") -> Fri | C12: =INT((12-5)/4)+1 -> 2 | D12: =COUNTIFS(Velocity!$I$2:$I$3001,"A",Velocity!$Q$2:$Q$3001,MOD(12-5,4),Velocity!$R$2:$R$3001,MOD($C12-1,Settings!$C$9)) -> 0 | E12: =COUNTIFS(Velocity!$I$2:$I$3001,"B",Velocity!$Q$2:$Q$3001,MOD(12-5,4),Velocity!$R$2:$R$3001,MOD($C12-1,Settings!$C$10)) -> 0 | F12: =COUNTIFS(Velocity!$I$2:$I$3001,"C",Velocity!$Q$2:$Q$3001,MOD(12-5,4),Velocity!$R$2:$R$3001,MOD($C12-1,Settings!$C$11)) -> 0 | G12: =COUNTIFS(Velocity!$I$2:$I$3001,"D",Velocity!$Q$2:$Q$3001,MOD(12-5,4),Velocity!$R$2:$R$3001,MOD($C12-1,Settings!$C$12)) -> 0 | H12: =SUM(D12:G12) -> 0 | I12: =Settings!$B$5 -> 50 | J12: =I12-H12 -> 50
A13: =Settings!$B$4+INT((13-5)/4)*7+MOD(13-5,4) -> 46329 | B13: =CHOOSE(MOD(13-5,4)+1,"Tue","Wed","Thu","Fri") -> Tue | C13: =INT((13-5)/4)+1 -> 3 | D13: =COUNTIFS(Velocity!$I$2:$I$3001,"A",Velocity!$Q$2:$Q$3001,MOD(13-5,4),Velocity!$R$2:$R$3001,MOD($C13-1,Settings!$C$9)) -> 0 | E13: =COUNTIFS(Velocity!$I$2:$I$3001,"B",Velocity!$Q$2:$Q$3001,MOD(13-5,4),Velocity!$R$2:$R$3001,MOD($C13-1,Settings!$C$10)) -> 0 | F13: =COUNTIFS(Velocity!$I$2:$I$3001,"C",Velocity!$Q$2:$Q$3001,MOD(13-5,4),Velocity!$R$2:$R$3001,MOD($C13-1,Settings!$C$11)) -> 0 | G13: =COUNTIFS(Velocity!$I$2:$I$3001,"D",Velocity!$Q$2:$Q$3001,MOD(13-5,4),Velocity!$R$2:$R$3001,MOD($C13-1,Settings!$C$12)) -> 0 | H13: =SUM(D13:G13) -> 0 | I13: =Settings!$B$5 -> 50 | J13: =I13-H13 -> 50
A14: =Settings!$B$4+INT((14-5)/4)*7+MOD(14-5,4) -> 46330 | B14: =CHOOSE(MOD(14-5,4)+1,"Tue","Wed","Thu","Fri") -> Wed | C14: =INT((14-5)/4)+1 -> 3 | D14: =COUNTIFS(Velocity!$I$2:$I$3001,"A",Velocity!$Q$2:$Q$3001,MOD(14-5,4),Velocity!$R$2:$R$3001,MOD($C14-1,Settings!$C$9)) -> 0 | E14: =COUNTIFS(Velocity!$I$2:$I$3001,"B",Velocity!$Q$2:$Q$3001,MOD(14-5,4),Velocity!$R$2:$R$3001,MOD($C14-1,Settings!$C$10)) -> 0 | F14: =COUNTIFS(Velocity!$I$2:$I$3001,"C",Velocity!$Q$2:$Q$3001,MOD(14-5,4),Velocity!$R$2:$R$3001,MOD($C14-1,Settings!$C$11)) -> 0 | G14: =COUNTIFS(Velocity!$I$2:$I$3001,"D",Velocity!$Q$2:$Q$3001,MOD(14-5,4),Velocity!$R$2:$R$3001,MOD($C14-1,Settings!$C$12)) -> 0 | H14: =SUM(D14:G14) -> 0 | I14: =Settings!$B$5 -> 50 | J14: =I14-H14 -> 50
A15: =Settings!$B$4+INT((15-5)/4)*7+MOD(15-5,4) -> 46331 | B15: =CHOOSE(MOD(15-5,4)+1,"Tue","Wed","Thu","Fri") -> Thu | C15: =INT((15-5)/4)+1 -> 3 | D15: =COUNTIFS(Velocity!$I$2:$I$3001,"A",Velocity!$Q$2:$Q$3001,MOD(15-5,4),Velocity!$R$2:$R$3001,MOD($C15-1,Settings!$C$9)) -> 0 | E15: =COUNTIFS(Velocity!$I$2:$I$3001,"B",Velocity!$Q$2:$Q$3001,MOD(15-5,4),Velocity!$R$2:$R$3001,MOD($C15-1,Settings!$C$10)) -> 0 | F15: =COUNTIFS(Velocity!$I$2:$I$3001,"C",Velocity!$Q$2:$Q$3001,MOD(15-5,4),Velocity!$R$2:$R$3001,MOD($C15-1,Settings!$C$11)) -> 0 | G15: =COUNTIFS(Velocity!$I$2:$I$3001,"D",Velocity!$Q$2:$Q$3001,MOD(15-5,4),Velocity!$R$2:$R$3001,MOD($C15-1,Settings!$C$12)) -> 0 | H15: =SUM(D15:G15) -> 0 | I15: =Settings!$B$5 -> 50 | J15: =I15-H15 -> 50
A16: =Settings!$B$4+INT((16-5)/4)*7+MOD(16-5,4) -> 46332 | B16: =CHOOSE(MOD(16-5,4)+1,"Tue","Wed","Thu","Fri") -> Fri | C16: =INT((16-5)/4)+1 -> 3 | D16: =COUNTIFS(Velocity!$I$2:$I$3001,"A",Velocity!$Q$2:$Q$3001,MOD(16-5,4),Velocity!$R$2:$R$3001,MOD($C16-1,Settings!$C$9)) -> 0 | E16: =COUNTIFS(Velocity!$I$2:$I$3001,"B",Velocity!$Q$2:$Q$3001,MOD(16-5,4),Velocity!$R$2:$R$3001,MOD($C16-1,Settings!$C$10)) -> 0 | F16: =COUNTIFS(Velocity!$I$2:$I$3001,"C",Velocity!$Q$2:$Q$3001,MOD(16-5,4),Velocity!$R$2:$R$3001,MOD($C16-1,Settings!$C$11)) -> 0 | G16: =COUNTIFS(Velocity!$I$2:$I$3001,"D",Velocity!$Q$2:$Q$3001,MOD(16-5,4),Velocity!$R$2:$R$3001,MOD($C16-1,Settings!$C$12)) -> 0 | H16: =SUM(D16:G16) -> 0 | I16: =Settings!$B$5 -> 50 | J16: =I16-H16 -> 50
A17: =Settings!$B$4+INT((17-5)/4)*7+MOD(17-5,4) -> 46336 | B17: =CHOOSE(MOD(17-5,4)+1,"Tue","Wed","Thu","Fri") -> Tue | C17: =INT((17-5)/4)+1 -> 4 | D17: =COUNTIFS(Velocity!$I$2:$I$3001,"A",Velocity!$Q$2:$Q$3001,MOD(17-5,4),Velocity!$R$2:$R$3001,MOD($C17-1,Settings!$C$9)) -> 0 | E17: =COUNTIFS(Velocity!$I$2:$I$3001,"B",Velocity!$Q$2:$Q$3001,MOD(17-5,4),Velocity!$R$2:$R$3001,MOD($C17-1,Settings!$C$10)) -> 0 | F17: =COUNTIFS(Velocity!$I$2:$I$3001,"C",Velocity!$Q$2:$Q$3001,MOD(17-5,4),Velocity!$R$2:$R$3001,MOD($C17-1,Settings!$C$11)) -> 0 | G17: =COUNTIFS(Velocity!$I$2:$I$3001,"D",Velocity!$Q$2:$Q$3001,MOD(17-5,4),Velocity!$R$2:$R$3001,MOD($C17-1,Settings!$C$12)) -> 0 | H17: =SUM(D17:G17) -> 0 | I17: =Settings!$B$5 -> 50 | J17: =I17-H17 -> 50
A18: =Settings!$B$4+INT((18-5)/4)*7+MOD(18-5,4) -> 46337 | B18: =CHOOSE(MOD(18-5,4)+1,"Tue","Wed","Thu","Fri") -> Wed | C18: =INT((18-5)/4)+1 -> 4 | D18: =COUNTIFS(Velocity!$I$2:$I$3001,"A",Velocity!$Q$2:$Q$3001,MOD(18-5,4),Velocity!$R$2:$R$3001,MOD($C18-1,Settings!$C$9)) -> 0 | E18: =COUNTIFS(Velocity!$I$2:$I$3001,"B",Velocity!$Q$2:$Q$3001,MOD(18-5,4),Velocity!$R$2:$R$3001,MOD($C18-1,Settings!$C$10)) -> 0 | F18: =COUNTIFS(Velocity!$I$2:$I$3001,"C",Velocity!$Q$2:$Q$3001,MOD(18-5,4),Velocity!$R$2:$R$3001,MOD($C18-1,Settings!$C$11)) -> 0 | G18: =COUNTIFS(Velocity!$I$2:$I$3001,"D",Velocity!$Q$2:$Q$3001,MOD(18-5,4),Velocity!$R$2:$R$3001,MOD($C18-1,Settings!$C$12)) -> 0 | H18: =SUM(D18:G18) -> 0 | I18: =Settings!$B$5 -> 50 | J18: =I18-H18 -> 50
A19: =Settings!$B$4+INT((19-5)/4)*7+MOD(19-5,4) -> 46338 | B19: =CHOOSE(MOD(19-5,4)+1,"Tue","Wed","Thu","Fri") -> Thu | C19: =INT((19-5)/4)+1 -> 4 | D19: =COUNTIFS(Velocity!$I$2:$I$3001,"A",Velocity!$Q$2:$Q$3001,MOD(19-5,4),Velocity!$R$2:$R$3001,MOD($C19-1,Settings!$C$9)) -> 0 | E19: =COUNTIFS(Velocity!$I$2:$I$3001,"B",Velocity!$Q$2:$Q$3001,MOD(19-5,4),Velocity!$R$2:$R$3001,MOD($C19-1,Settings!$C$10)) -> 0 | F19: =COUNTIFS(Velocity!$I$2:$I$3001,"C",Velocity!$Q$2:$Q$3001,MOD(19-5,4),Velocity!$R$2:$R$3001,MOD($C19-1,Settings!$C$11)) -> 0 | G19: =COUNTIFS(Velocity!$I$2:$I$3001,"D",Velocity!$Q$2:$Q$3001,MOD(19-5,4),Velocity!$R$2:$R$3001,MOD($C19-1,Settings!$C$12)) -> 0 | H19: =SUM(D19:G19) -> 0 | I19: =Settings!$B$5 -> 50 | J19: =I19-H19 -> 50
A20: =Settings!$B$4+INT((20-5)/4)*7+MOD(20-5,4) -> 46339 | B20: =CHOOSE(MOD(20-5,4)+1,"Tue","Wed","Thu","Fri") -> Fri | C20: =INT((20-5)/4)+1 -> 4 | D20: =COUNTIFS(Velocity!$I$2:$I$3001,"A",Velocity!$Q$2:$Q$3001,MOD(20-5,4),Velocity!$R$2:$R$3001,MOD($C20-1,Settings!$C$9)) -> 0 | E20: =COUNTIFS(Velocity!$I$2:$I$3001,"B",Velocity!$Q$2:$Q$3001,MOD(20-5,4),Velocity!$R$2:$R$3001,MOD($C20-1,Settings!$C$10)) -> 0 | F20: =COUNTIFS(Velocity!$I$2:$I$3001,"C",Velocity!$Q$2:$Q$3001,MOD(20-5,4),Velocity!$R$2:$R$3001,MOD($C20-1,Settings!$C$11)) -> 0 | G20: =COUNTIFS(Velocity!$I$2:$I$3001,"D",Velocity!$Q$2:$Q$3001,MOD(20-5,4),Velocity!$R$2:$R$3001,MOD($C20-1,Settings!$C$12)) -> 0 | H20: =SUM(D20:G20) -> 0 | I20: =Settings!$B$5 -> 50 | J20: =I20-H20 -> 50
A21: =Settings!$B$4+INT((21-5)/4)*7+MOD(21-5,4) -> 46343 | B21: =CHOOSE(MOD(21-5,4)+1,"Tue","Wed","Thu","Fri") -> Tue | C21: =INT((21-5)/4)+1 -> 5 | D21: =COUNTIFS(Velocity!$I$2:$I$3001,"A",Velocity!$Q$2:$Q$3001,MOD(21-5,4),Velocity!$R$2:$R$3001,MOD($C21-1,Settings!$C$9)) -> 0 | E21: =COUNTIFS(Velocity!$I$2:$I$3001,"B",Velocity!$Q$2:$Q$3001,MOD(21-5,4),Velocity!$R$2:$R$3001,MOD($C21-1,Settings!$C$10)) -> 0 | F21: =COUNTIFS(Velocity!$I$2:$I$3001,"C",Velocity!$Q$2:$Q$3001,MOD(21-5,4),Velocity!$R$2:$R$3001,MOD($C21-1,Settings!$C$11)) -> 0 | G21: =COUNTIFS(Velocity!$I$2:$I$3001,"D",Velocity!$Q$2:$Q$3001,MOD(21-5,4),Velocity!$R$2:$R$3001,MOD($C21-1,Settings!$C$12)) -> 0 | H21: =SUM(D21:G21) -> 0 | I21: =Settings!$B$5 -> 50 | J21: =I21-H21 -> 50
A22: =Settings!$B$4+INT((22-5)/4)*7+MOD(22-5,4) -> 46344 | B22: =CHOOSE(MOD(22-5,4)+1,"Tue","Wed","Thu","Fri") -> Wed | C22: =INT((22-5)/4)+1 -> 5 | D22: =COUNTIFS(Velocity!$I$2:$I$3001,"A",Velocity!$Q$2:$Q$3001,MOD(22-5,4),Velocity!$R$2:$R$3001,MOD($C22-1,Settings!$C$9)) -> 0 | E22: =COUNTIFS(Velocity!$I$2:$I$3001,"B",Velocity!$Q$2:$Q$3001,MOD(22-5,4),Velocity!$R$2:$R$3001,MOD($C22-1,Settings!$C$10)) -> 0 | F22: =COUNTIFS(Velocity!$I$2:$I$3001,"C",Velocity!$Q$2:$Q$3001,MOD(22-5,4),Velocity!$R$2:$R$3001,MOD($C22-1,Settings!$C$11)) -> 0 | G22: =COUNTIFS(Velocity!$I$2:$I$3001,"D",Velocity!$Q$2:$Q$3001,MOD(22-5,4),Velocity!$R$2:$R$3001,MOD($C22-1,Settings!$C$12)) -> 0 | H22: =SUM(D22:G22) -> 0 | I22: =Settings!$B$5 -> 50 | J22: =I22-H22 -> 50
A23: =Settings!$B$4+INT((23-5)/4)*7+MOD(23-5,4) -> 46345 | B23: =CHOOSE(MOD(23-5,4)+1,"Tue","Wed","Thu","Fri") -> Thu | C23: =INT((23-5)/4)+1 -> 5 | D23: =COUNTIFS(Velocity!$I$2:$I$3001,"A",Velocity!$Q$2:$Q$3001,MOD(23-5,4),Velocity!$R$2:$R$3001,MOD($C23-1,Settings!$C$9)) -> 0 | E23: =COUNTIFS(Velocity!$I$2:$I$3001,"B",Velocity!$Q$2:$Q$3001,MOD(23-5,4),Velocity!$R$2:$R$3001,MOD($C23-1,Settings!$C$10)) -> 0 | F23: =COUNTIFS(Velocity!$I$2:$I$3001,"C",Velocity!$Q$2:$Q$3001,MOD(23-5,4),Velocity!$R$2:$R$3001,MOD($C23-1,Settings!$C$11)) -> 0 | G23: =COUNTIFS(Velocity!$I$2:$I$3001,"D",Velocity!$Q$2:$Q$3001,MOD(23-5,4),Velocity!$R$2:$R$3001,MOD($C23-1,Settings!$C$12)) -> 0 | H23: =SUM(D23:G23) -> 0 | I23: =Settings!$B$5 -> 50 | J23: =I23-H23 -> 50
A24: =Settings!$B$4+INT((24-5)/4)*7+MOD(24-5,4) -> 46346 | B24: =CHOOSE(MOD(24-5,4)+1,"Tue","Wed","Thu","Fri") -> Fri | C24: =INT((24-5)/4)+1 -> 5 | D24: =COUNTIFS(Velocity!$I$2:$I$3001,"A",Velocity!$Q$2:$Q$3001,MOD(24-5,4),Velocity!$R$2:$R$3001,MOD($C24-1,Settings!$C$9)) -> 0 | E24: =COUNTIFS(Velocity!$I$2:$I$3001,"B",Velocity!$Q$2:$Q$3001,MOD(24-5,4),Velocity!$R$2:$R$3001,MOD($C24-1,Settings!$C$10)) -> 0 | F24: =COUNTIFS(Velocity!$I$2:$I$3001,"C",Velocity!$Q$2:$Q$3001,MOD(24-5,4),Velocity!$R$2:$R$3001,MOD($C24-1,Settings!$C$11)) -> 0 | G24: =COUNTIFS(Velocity!$I$2:$I$3001,"D",Velocity!$Q$2:$Q$3001,MOD(24-5,4),Velocity!$R$2:$R$3001,MOD($C24-1,Settings!$C$12)) -> 0 | H24: =SUM(D24:G24) -> 0 | I24: =Settings!$B$5 -> 50 | J24: =I24-H24 -> 50
A25: =Settings!$B$4+INT((25-5)/4)*7+MOD(25-5,4) -> 46350 | B25: =CHOOSE(MOD(25-5,4)+1,"Tue","Wed","Thu","Fri") -> Tue | C25: =INT((25-5)/4)+1 -> 6 | D25: =COUNTIFS(Velocity!$I$2:$I$3001,"A",Velocity!$Q$2:$Q$3001,MOD(25-5,4),Velocity!$R$2:$R$3001,MOD($C25-1,Settings!$C$9)) -> 0 | E25: =COUNTIFS(Velocity!$I$2:$I$3001,"B",Velocity!$Q$2:$Q$3001,MOD(25-5,4),Velocity!$R$2:$R$3001,MOD($C25-1,Settings!$C$10)) -> 0 | F25: =COUNTIFS(Velocity!$I$2:$I$3001,"C",Velocity!$Q$2:$Q$3001,MOD(25-5,4),Velocity!$R$2:$R$3001,MOD($C25-1,Settings!$C$11)) -> 0 | G25: =COUNTIFS(Velocity!$I$2:$I$3001,"D",Velocity!$Q$2:$Q$3001,MOD(25-5,4),Velocity!$R$2:$R$3001,MOD($C25-1,Settings!$C$12)) -> 0 | H25: =SUM(D25:G25) -> 0 | I25: =Settings!$B$5 -> 50 | J25: =I25-H25 -> 50
A26: =Settings!$B$4+INT((26-5)/4)*7+MOD(26-5,4) -> 46351 | B26: =CHOOSE(MOD(26-5,4)+1,"Tue","Wed","Thu","Fri") -> Wed | C26: =INT((26-5)/4)+1 -> 6 | D26: =COUNTIFS(Velocity!$I$2:$I$3001,"A",Velocity!$Q$2:$Q$3001,MOD(26-5,4),Velocity!$R$2:$R$3001,MOD($C26-1,Settings!$C$9)) -> 0 | E26: =COUNTIFS(Velocity!$I$2:$I$3001,"B",Velocity!$Q$2:$Q$3001,MOD(26-5,4),Velocity!$R$2:$R$3001,MOD($C26-1,Settings!$C$10)) -> 0 | F26: =COUNTIFS(Velocity!$I$2:$I$3001,"C",Velocity!$Q$2:$Q$3001,MOD(26-5,4),Velocity!$R$2:$R$3001,MOD($C26-1,Settings!$C$11)) -> 0 | G26: =COUNTIFS(Velocity!$I$2:$I$3001,"D",Velocity!$Q$2:$Q$3001,MOD(26-5,4),Velocity!$R$2:$R$3001,MOD($C26-1,Settings!$C$12)) -> 0 | H26: =SUM(D26:G26) -> 0 | I26: =Settings!$B$5 -> 50 | J26: =I26-H26 -> 50
A27: =Settings!$B$4+INT((27-5)/4)*7+MOD(27-5,4) -> 46352 | B27: =CHOOSE(MOD(27-5,4)+1,"Tue","Wed","Thu","Fri") -> Thu | C27: =INT((27-5)/4)+1 -> 6 | D27: =COUNTIFS(Velocity!$I$2:$I$3001,"A",Velocity!$Q$2:$Q$3001,MOD(27-5,4),Velocity!$R$2:$R$3001,MOD($C27-1,Settings!$C$9)) -> 0 | E27: =COUNTIFS(Velocity!$I$2:$I$3001,"B",Velocity!$Q$2:$Q$3001,MOD(27-5,4),Velocity!$R$2:$R$3001,MOD($C27-1,Settings!$C$10)) -> 0 | F27: =COUNTIFS(Velocity!$I$2:$I$3001,"C",Velocity!$Q$2:$Q$3001,MOD(27-5,4),Velocity!$R$2:$R$3001,MOD($C27-1,Settings!$C$11)) -> 0 | G27: =COUNTIFS(Velocity!$I$2:$I$3001,"D",Velocity!$Q$2:$Q$3001,MOD(27-5,4),Velocity!$R$2:$R$3001,MOD($C27-1,Settings!$C$12)) -> 0 | H27: =SUM(D27:G27) -> 0 | I27: =Settings!$B$5 -> 50 | J27: =I27-H27 -> 50
A28: =Settings!$B$4+INT((28-5)/4)*7+MOD(28-5,4) -> 46353 | B28: =CHOOSE(MOD(28-5,4)+1,"Tue","Wed","Thu","Fri") -> Fri | C28: =INT((28-5)/4)+1 -> 6 | D28: =COUNTIFS(Velocity!$I$2:$I$3001,"A",Velocity!$Q$2:$Q$3001,MOD(28-5,4),Velocity!$R$2:$R$3001,MOD($C28-1,Settings!$C$9)) -> 0 | E28: =COUNTIFS(Velocity!$I$2:$I$3001,"B",Velocity!$Q$2:$Q$3001,MOD(28-5,4),Velocity!$R$2:$R$3001,MOD($C28-1,Settings!$C$10)) -> 0 | F28: =COUNTIFS(Velocity!$I$2:$I$3001,"C",Velocity!$Q$2:$Q$3001,MOD(28-5,4),Velocity!$R$2:$R$3001,MOD($C28-1,Settings!$C$11)) -> 0 | G28: =COUNTIFS(Velocity!$I$2:$I$3001,"D",Velocity!$Q$2:$Q$3001,MOD(28-5,4),Velocity!$R$2:$R$3001,MOD($C28-1,Settings!$C$12)) -> 0 | H28: =SUM(D28:G28) -> 0 | I28: =Settings!$B$5 -> 50 | J28: =I28-H28 -> 50
A29: =Settings!$B$4+INT((29-5)/4)*7+MOD(29-5,4) -> 46357 | B29: =CHOOSE(MOD(29-5,4)+1,"Tue","Wed","Thu","Fri") -> Tue | C29: =INT((29-5)/4)+1 -> 7 | D29: =COUNTIFS(Velocity!$I$2:$I$3001,"A",Velocity!$Q$2:$Q$3001,MOD(29-5,4),Velocity!$R$2:$R$3001,MOD($C29-1,Settings!$C$9)) -> 0 | E29: =COUNTIFS(Velocity!$I$2:$I$3001,"B",Velocity!$Q$2:$Q$3001,MOD(29-5,4),Velocity!$R$2:$R$3001,MOD($C29-1,Settings!$C$10)) -> 0 | F29: =COUNTIFS(Velocity!$I$2:$I$3001,"C",Velocity!$Q$2:$Q$3001,MOD(29-5,4),Velocity!$R$2:$R$3001,MOD($C29-1,Settings!$C$11)) -> 0 | G29: =COUNTIFS(Velocity!$I$2:$I$3001,"D",Velocity!$Q$2:$Q$3001,MOD(29-5,4),Velocity!$R$2:$R$3001,MOD($C29-1,Settings!$C$12)) -> 0 | H29: =SUM(D29:G29) -> 0 | I29: =Settings!$B$5 -> 50 | J29: =I29-H29 -> 50
A30: =Settings!$B$4+INT((30-5)/4)*7+MOD(30-5,4) -> 46358 | B30: =CHOOSE(MOD(30-5,4)+1,"Tue","Wed","Thu","Fri") -> Wed | C30: =INT((30-5)/4)+1 -> 7 | D30: =COUNTIFS(Velocity!$I$2:$I$3001,"A",Velocity!$Q$2:$Q$3001,MOD(30-5,4),Velocity!$R$2:$R$3001,MOD($C30-1,Settings!$C$9)) -> 0 | E30: =COUNTIFS(Velocity!$I$2:$I$3001,"B",Velocity!$Q$2:$Q$3001,MOD(30-5,4),Velocity!$R$2:$R$3001,MOD($C30-1,Settings!$C$10)) -> 0 | F30: =COUNTIFS(Velocity!$I$2:$I$3001,"C",Velocity!$Q$2:$Q$3001,MOD(30-5,4),Velocity!$R$2:$R$3001,MOD($C30-1,Settings!$C$11)) -> 0 | G30: =COUNTIFS(Velocity!$I$2:$I$3001,"D",Velocity!$Q$2:$Q$3001,MOD(30-5,4),Velocity!$R$2:$R$3001,MOD($C30-1,Settings!$C$12)) -> 0 | H30: =SUM(D30:G30) -> 0 | I30: =Settings!$B$5 -> 50 | J30: =I30-H30 -> 50
A31: =Settings!$B$4+INT((31-5)/4)*7+MOD(31-5,4) -> 46359 | B31: =CHOOSE(MOD(31-5,4)+1,"Tue","Wed","Thu","Fri") -> Thu | C31: =INT((31-5)/4)+1 -> 7 | D31: =COUNTIFS(Velocity!$I$2:$I$3001,"A",Velocity!$Q$2:$Q$3001,MOD(31-5,4),Velocity!$R$2:$R$3001,MOD($C31-1,Settings!$C$9)) -> 0 | E31: =COUNTIFS(Velocity!$I$2:$I$3001,"B",Velocity!$Q$2:$Q$3001,MOD(31-5,4),Velocity!$R$2:$R$3001,MOD($C31-1,Settings!$C$10)) -> 0 | F31: =COUNTIFS(Velocity!$I$2:$I$3001,"C",Velocity!$Q$2:$Q$3001,MOD(31-5,4),Velocity!$R$2:$R$3001,MOD($C31-1,Settings!$C$11)) -> 0 | G31: =COUNTIFS(Velocity!$I$2:$I$3001,"D",Velocity!$Q$2:$Q$3001,MOD(31-5,4),Velocity!$R$2:$R$3001,MOD($C31-1,Settings!$C$12)) -> 0 | H31: =SUM(D31:G31) -> 0 | I31: =Settings!$B$5 -> 50 | J31: =I31-H31 -> 50
A32: =Settings!$B$4+INT((32-5)/4)*7+MOD(32-5,4) -> 46360 | B32: =CHOOSE(MOD(32-5,4)+1,"Tue","Wed","Thu","Fri") -> Fri | C32: =INT((32-5)/4)+1 -> 7 | D32: =COUNTIFS(Velocity!$I$2:$I$3001,"A",Velocity!$Q$2:$Q$3001,MOD(32-5,4),Velocity!$R$2:$R$3001,MOD($C32-1,Settings!$C$9)) -> 0 | E32: =COUNTIFS(Velocity!$I$2:$I$3001,"B",Velocity!$Q$2:$Q$3001,MOD(32-5,4),Velocity!$R$2:$R$3001,MOD($C32-1,Settings!$C$10)) -> 0 | F32: =COUNTIFS(Velocity!$I$2:$I$3001,"C",Velocity!$Q$2:$Q$3001,MOD(32-5,4),Velocity!$R$2:$R$3001,MOD($C32-1,Settings!$C$11)) -> 0 | G32: =COUNTIFS(Velocity!$I$2:$I$3001,"D",Velocity!$Q$2:$Q$3001,MOD(32-5,4),Velocity!$R$2:$R$3001,MOD($C32-1,Settings!$C$12)) -> 0 | H32: =SUM(D32:G32) -> 0 | I32: =Settings!$B$5 -> 50 | J32: =I32-H32 -> 50
A33: =Settings!$B$4+INT((33-5)/4)*7+MOD(33-5,4) -> 46364 | B33: =CHOOSE(MOD(33-5,4)+1,"Tue","Wed","Thu","Fri") -> Tue | C33: =INT((33-5)/4)+1 -> 8 | D33: =COUNTIFS(Velocity!$I$2:$I$3001,"A",Velocity!$Q$2:$Q$3001,MOD(33-5,4),Velocity!$R$2:$R$3001,MOD($C33-1,Settings!$C$9)) -> 0 | E33: =COUNTIFS(Velocity!$I$2:$I$3001,"B",Velocity!$Q$2:$Q$3001,MOD(33-5,4),Velocity!$R$2:$R$3001,MOD($C33-1,Settings!$C$10)) -> 0 | F33: =COUNTIFS(Velocity!$I$2:$I$3001,"C",Velocity!$Q$2:$Q$3001,MOD(33-5,4),Velocity!$R$2:$R$3001,MOD($C33-1,Settings!$C$11)) -> 0 | G33: =COUNTIFS(Velocity!$I$2:$I$3001,"D",Velocity!$Q$2:$Q$3001,MOD(33-5,4),Velocity!$R$2:$R$3001,MOD($C33-1,Settings!$C$12)) -> 0 | H33: =SUM(D33:G33) -> 0 | I33: =Settings!$B$5 -> 50 | J33: =I33-H33 -> 50
A34: =Settings!$B$4+INT((34-5)/4)*7+MOD(34-5,4) -> 46365 | B34: =CHOOSE(MOD(34-5,4)+1,"Tue","Wed","Thu","Fri") -> Wed | C34: =INT((34-5)/4)+1 -> 8 | D34: =COUNTIFS(Velocity!$I$2:$I$3001,"A",Velocity!$Q$2:$Q$3001,MOD(34-5,4),Velocity!$R$2:$R$3001,MOD($C34-1,Settings!$C$9)) -> 0 | E34: =COUNTIFS(Velocity!$I$2:$I$3001,"B",Velocity!$Q$2:$Q$3001,MOD(34-5,4),Velocity!$R$2:$R$3001,MOD($C34-1,Settings!$C$10)) -> 0 | F34: =COUNTIFS(Velocity!$I$2:$I$3001,"C",Velocity!$Q$2:$Q$3001,MOD(34-5,4),Velocity!$R$2:$R$3001,MOD($C34-1,Settings!$C$11)) -> 0 | G34: =COUNTIFS(Velocity!$I$2:$I$3001,"D",Velocity!$Q$2:$Q$3001,MOD(34-5,4),Velocity!$R$2:$R$3001,MOD($C34-1,Settings!$C$12)) -> 0 | H34: =SUM(D34:G34) -> 0 | I34: =Settings!$B$5 -> 50 | J34: =I34-H34 -> 50
A35: =Settings!$B$4+INT((35-5)/4)*7+MOD(35-5,4) -> 46366 | B35: =CHOOSE(MOD(35-5,4)+1,"Tue","Wed","Thu","Fri") -> Thu | C35: =INT((35-5)/4)+1 -> 8 | D35: =COUNTIFS(Velocity!$I$2:$I$3001,"A",Velocity!$Q$2:$Q$3001,MOD(35-5,4),Velocity!$R$2:$R$3001,MOD($C35-1,Settings!$C$9)) -> 0 | E35: =COUNTIFS(Velocity!$I$2:$I$3001,"B",Velocity!$Q$2:$Q$3001,MOD(35-5,4),Velocity!$R$2:$R$3001,MOD($C35-1,Settings!$C$10)) -> 0 | F35: =COUNTIFS(Velocity!$I$2:$I$3001,"C",Velocity!$Q$2:$Q$3001,MOD(35-5,4),Velocity!$R$2:$R$3001,MOD($C35-1,Settings!$C$11)) -> 0 | G35: =COUNTIFS(Velocity!$I$2:$I$3001,"D",Velocity!$Q$2:$Q$3001,MOD(35-5,4),Velocity!$R$2:$R$3001,MOD($C35-1,Settings!$C$12)) -> 0 | H35: =SUM(D35:G35) -> 0 | I35: =Settings!$B$5 -> 50 | J35: =I35-H35 -> 50
A36: =Settings!$B$4+INT((36-5)/4)*7+MOD(36-5,4) -> 46367 | B36: =CHOOSE(MOD(36-5,4)+1,"Tue","Wed","Thu","Fri") -> Fri | C36: =INT((36-5)/4)+1 -> 8 | D36: =COUNTIFS(Velocity!$I$2:$I$3001,"A",Velocity!$Q$2:$Q$3001,MOD(36-5,4),Velocity!$R$2:$R$3001,MOD($C36-1,Settings!$C$9)) -> 0 | E36: =COUNTIFS(Velocity!$I$2:$I$3001,"B",Velocity!$Q$2:$Q$3001,MOD(36-5,4),Velocity!$R$2:$R$3001,MOD($C36-1,Settings!$C$10)) -> 0 | F36: =COUNTIFS(Velocity!$I$2:$I$3001,"C",Velocity!$Q$2:$Q$3001,MOD(36-5,4),Velocity!$R$2:$R$3001,MOD($C36-1,Settings!$C$11)) -> 0 | G36: =COUNTIFS(Velocity!$I$2:$I$3001,"D",Velocity!$Q$2:$Q$3001,MOD(36-5,4),Velocity!$R$2:$R$3001,MOD($C36-1,Settings!$C$12)) -> 0 | H36: =SUM(D36:G36) -> 0 | I36: =Settings!$B$5 -> 50 | J36: =I36-H36 -> 50
A37: =Settings!$B$4+INT((37-5)/4)*7+MOD(37-5,4) -> 46371 | B37: =CHOOSE(MOD(37-5,4)+1,"Tue","Wed","Thu","Fri") -> Tue | C37: =INT((37-5)/4)+1 -> 9 | D37: =COUNTIFS(Velocity!$I$2:$I$3001,"A",Velocity!$Q$2:$Q$3001,MOD(37-5,4),Velocity!$R$2:$R$3001,MOD($C37-1,Settings!$C$9)) -> 0 | E37: =COUNTIFS(Velocity!$I$2:$I$3001,"B",Velocity!$Q$2:$Q$3001,MOD(37-5,4),Velocity!$R$2:$R$3001,MOD($C37-1,Settings!$C$10)) -> 0 | F37: =COUNTIFS(Velocity!$I$2:$I$3001,"C",Velocity!$Q$2:$Q$3001,MOD(37-5,4),Velocity!$R$2:$R$3001,MOD($C37-1,Settings!$C$11)) -> 0 | G37: =COUNTIFS(Velocity!$I$2:$I$3001,"D",Velocity!$Q$2:$Q$3001,MOD(37-5,4),Velocity!$R$2:$R$3001,MOD($C37-1,Settings!$C$12)) -> 0 | H37: =SUM(D37:G37) -> 0 | I37: =Settings!$B$5 -> 50 | J37: =I37-H37 -> 50
A38: =Settings!$B$4+INT((38-5)/4)*7+MOD(38-5,4) -> 46372 | B38: =CHOOSE(MOD(38-5,4)+1,"Tue","Wed","Thu","Fri") -> Wed | C38: =INT((38-5)/4)+1 -> 9 | D38: =COUNTIFS(Velocity!$I$2:$I$3001,"A",Velocity!$Q$2:$Q$3001,MOD(38-5,4),Velocity!$R$2:$R$3001,MOD($C38-1,Settings!$C$9)) -> 0 | E38: =COUNTIFS(Velocity!$I$2:$I$3001,"B",Velocity!$Q$2:$Q$3001,MOD(38-5,4),Velocity!$R$2:$R$3001,MOD($C38-1,Settings!$C$10)) -> 0 | F38: =COUNTIFS(Velocity!$I$2:$I$3001,"C",Velocity!$Q$2:$Q$3001,MOD(38-5,4),Velocity!$R$2:$R$3001,MOD($C38-1,Settings!$C$11)) -> 0 | G38: =COUNTIFS(Velocity!$I$2:$I$3001,"D",Velocity!$Q$2:$Q$3001,MOD(38-5,4),Velocity!$R$2:$R$3001,MOD($C38-1,Settings!$C$12)) -> 0 | H38: =SUM(D38:G38) -> 0 | I38: =Settings!$B$5 -> 50 | J38: =I38-H38 -> 50
A39: =Settings!$B$4+INT((39-5)/4)*7+MOD(39-5,4) -> 46373 | B39: =CHOOSE(MOD(39-5,4)+1,"Tue","Wed","Thu","Fri") -> Thu | C39: =INT((39-5)/4)+1 -> 9 | D39: =COUNTIFS(Velocity!$I$2:$I$3001,"A",Velocity!$Q$2:$Q$3001,MOD(39-5,4),Velocity!$R$2:$R$3001,MOD($C39-1,Settings!$C$9)) -> 0 | E39: =COUNTIFS(Velocity!$I$2:$I$3001,"B",Velocity!$Q$2:$Q$3001,MOD(39-5,4),Velocity!$R$2:$R$3001,MOD($C39-1,Settings!$C$10)) -> 0 | F39: =COUNTIFS(Velocity!$I$2:$I$3001,"C",Velocity!$Q$2:$Q$3001,MOD(39-5,4),Velocity!$R$2:$R$3001,MOD($C39-1,Settings!$C$11)) -> 0 | G39: =COUNTIFS(Velocity!$I$2:$I$3001,"D",Velocity!$Q$2:$Q$3001,MOD(39-5,4),Velocity!$R$2:$R$3001,MOD($C39-1,Settings!$C$12)) -> 0 | H39: =SUM(D39:G39) -> 0 | I39: =Settings!$B$5 -> 50 | J39: =I39-H39 -> 50
A40: =Settings!$B$4+INT((40-5)/4)*7+MOD(40-5,4) -> 46374 | B40: =CHOOSE(MOD(40-5,4)+1,"Tue","Wed","Thu","Fri") -> Fri | C40: =INT((40-5)/4)+1 -> 9 | D40: =COUNTIFS(Velocity!$I$2:$I$3001,"A",Velocity!$Q$2:$Q$3001,MOD(40-5,4),Velocity!$R$2:$R$3001,MOD($C40-1,Settings!$C$9)) -> 0 | E40: =COUNTIFS(Velocity!$I$2:$I$3001,"B",Velocity!$Q$2:$Q$3001,MOD(40-5,4),Velocity!$R$2:$R$3001,MOD($C40-1,Settings!$C$10)) -> 0 | F40: =COUNTIFS(Velocity!$I$2:$I$3001,"C",Velocity!$Q$2:$Q$3001,MOD(40-5,4),Velocity!$R$2:$R$3001,MOD($C40-1,Settings!$C$11)) -> 0 | G40: =COUNTIFS(Velocity!$I$2:$I$3001,"D",Velocity!$Q$2:$Q$3001,MOD(40-5,4),Velocity!$R$2:$R$3001,MOD($C40-1,Settings!$C$12)) -> 0 | H40: =SUM(D40:G40) -> 0 | I40: =Settings!$B$5 -> 50 | J40: =I40-H40 -> 50
A41: =Settings!$B$4+INT((41-5)/4)*7+MOD(41-5,4) -> 46378 | B41: =CHOOSE(MOD(41-5,4)+1,"Tue","Wed","Thu","Fri") -> Tue | C41: =INT((41-5)/4)+1 -> 10 | D41: =COUNTIFS(Velocity!$I$2:$I$3001,"A",Velocity!$Q$2:$Q$3001,MOD(41-5,4),Velocity!$R$2:$R$3001,MOD($C41-1,Settings!$C$9)) -> 0 | E41: =COUNTIFS(Velocity!$I$2:$I$3001,"B",Velocity!$Q$2:$Q$3001,MOD(41-5,4),Velocity!$R$2:$R$3001,MOD($C41-1,Settings!$C$10)) -> 0 | F41: =COUNTIFS(Velocity!$I$2:$I$3001,"C",Velocity!$Q$2:$Q$3001,MOD(41-5,4),Velocity!$R$2:$R$3001,MOD($C41-1,Settings!$C$11)) -> 0 | G41: =COUNTIFS(Velocity!$I$2:$I$3001,"D",Velocity!$Q$2:$Q$3001,MOD(41-5,4),Velocity!$R$2:$R$3001,MOD($C41-1,Settings!$C$12)) -> 0 | H41: =SUM(D41:G41) -> 0 | I41: =Settings!$B$5 -> 50 | J41: =I41-H41 -> 50
...

Sheet Daily Count Sheet
A1: Daily Cycle Count Sheet: Aurora
A3: Count date | B3: =Calendar!A5 -> 46315 | D3: =IF(OR(H3<0,H3>3,B3<Settings!$B$4),"⚠ Not a counting day in this schedule","") | G3: helpers → | H3: =IF(B3<Settings!$B$4,-1,MOD(B3-Settings!$B$4,7)) -> 0 | I3: =INT((B3-Settings!$B$4)/7) -> 0
A4: SKUs to count | B4: =COUNT(Velocity!$S$2:$S$3001) -> 0 | C4: ="A "&COUNTIFS(Velocity!$S$2:$S$3001,1,Velocity!$I$2:$I$3001,"A")&" · B "&COUNTIFS(Velocity!$S$2:$S$3001,1,Velocity!$I$2:$I$3001,"B")&" · C "&COUNTIFS(Velocity!$S$2:$S$3001,1,Velocity!$I$2:$I$3001,"C")&" · D "&COUNTIFS(Velocity!$S$2:$S$3001,1,Velocity!$I$2:$I$3001,"D") -> A 0 · B 0 · C 0 · D 0
A5: Counted by: ____________________ Blind count: system quantity is not shown. Count A SKUs before picking starts. Count every bin for each SKU.
A7: # | B7: SKU | C7: Product | D7: Class | E7: Last counted | F7: Counted qty | G7: Notes
A8: =IF(1<=$B$4,1,"") | B8: =IF($A8="","",INDEX(Velocity!$A$2:$A$3001,MATCH($A8,Velocity!$T$2:$T$3001,0))) | C8: =IF($A8="","",INDEX(Velocity!$B$2:$B$3001,MATCH($A8,Velocity!$T$2:$T$3001,0))) | D8: =IF($A8="","",INDEX(Velocity!$I$2:$I$3001,MATCH($A8,Velocity!$T$2:$T$3001,0))) | E8: =IF($A8="","",IF(INDEX(Velocity!$F$2:$F$3001,MATCH($A8,Velocity!$T$2:$T$3001,0))="","Never",INDEX(Velocity!$F$2:$F$3001,MATCH($A8,Velocity!$T$2:$T$3001,0))))
A9: =IF(2<=$B$4,2,"") | B9: =IF($A9="","",INDEX(Velocity!$A$2:$A$3001,MATCH($A9,Velocity!$T$2:$T$3001,0))) | C9: =IF($A9="","",INDEX(Velocity!$B$2:$B$3001,MATCH($A9,Velocity!$T$2:$T$3001,0))) | D9: =IF($A9="","",INDEX(Velocity!$I$2:$I$3001,MATCH($A9,Velocity!$T$2:$T$3001,0))) | E9: =IF($A9="","",IF(INDEX(Velocity!$F$2:$F$3001,MATCH($A9,Velocity!$T$2:$T$3001,0))="","Never",INDEX(Velocity!$F$2:$F$3001,MATCH($A9,Velocity!$T$2:$T$3001,0))))
A10: =IF(3<=$B$4,3,"") | B10: =IF($A10="","",INDEX(Velocity!$A$2:$A$3001,MATCH($A10,Velocity!$T$2:$T$3001,0))) | C10: =IF($A10="","",INDEX(Velocity!$B$2:$B$3001,MATCH($A10,Velocity!$T$2:$T$3001,0))) | D10: =IF($A10="","",INDEX(Velocity!$I$2:$I$3001,MATCH($A10,Velocity!$T$2:$T$3001,0))) | E10: =IF($A10="","",IF(INDEX(Velocity!$F$2:$F$3001,MATCH($A10,Velocity!$T$2:$T$3001,0))="","Never",INDEX(Velocity!$F$2:$F$3001,MATCH($A10,Velocity!$T$2:$T$3001,0))))
A11: =IF(4<=$B$4,4,"") | B11: =IF($A11="","",INDEX(Velocity!$A$2:$A$3001,MATCH($A11,Velocity!$T$2:$T$3001,0))) | C11: =IF($A11="","",INDEX(Velocity!$B$2:$B$3001,MATCH($A11,Velocity!$T$2:$T$3001,0))) | D11: =IF($A11="","",INDEX(Velocity!$I$2:$I$3001,MATCH($A11,Velocity!$T$2:$T$3001,0))) | E11: =IF($A11="","",IF(INDEX(Velocity!$F$2:$F$3001,MATCH($A11,Velocity!$T$2:$T$3001,0))="","Never",INDEX(Velocity!$F$2:$F$3001,MATCH($A11,Velocity!$T$2:$T$3001,0))))
A12: =IF(5<=$B$4,5,"") | B12: =IF($A12="","",INDEX(Velocity!$A$2:$A$3001,MATCH($A12,Velocity!$T$2:$T$3001,0))) | C12: =IF($A12="","",INDEX(Velocity!$B$2:$B$3001,MATCH($A12,Velocity!$T$2:$T$3001,0))) | D12: =IF($A12="","",INDEX(Velocity!$I$2:$I$3001,MATCH($A12,Velocity!$T$2:$T$3001,0))) | E12: =IF($A12="","",IF(INDEX(Velocity!$F$2:$F$3001,MATCH($A12,Velocity!$T$2:$T$3001,0))="","Never",INDEX(Velocity!$F$2:$F$3001,MATCH($A12,Velocity!$T$2:$T$3001,0))))
A13: =IF(6<=$B$4,6,"") | B13: =IF($A13="","",INDEX(Velocity!$A$2:$A$3001,MATCH($A13,Velocity!$T$2:$T$3001,0))) | C13: =IF($A13="","",INDEX(Velocity!$B$2:$B$3001,MATCH($A13,Velocity!$T$2:$T$3001,0))) | D13: =IF($A13="","",INDEX(Velocity!$I$2:$I$3001,MATCH($A13,Velocity!$T$2:$T$3001,0))) | E13: =IF($A13="","",IF(INDEX(Velocity!$F$2:$F$3001,MATCH($A13,Velocity!$T$2:$T$3001,0))="","Never",INDEX(Velocity!$F$2:$F$3001,MATCH($A13,Velocity!$T$2:$T$3001,0))))
A14: =IF(7<=$B$4,7,"") | B14: =IF($A14="","",INDEX(Velocity!$A$2:$A$3001,MATCH($A14,Velocity!$T$2:$T$3001,0))) | C14: =IF($A14="","",INDEX(Velocity!$B$2:$B$3001,MATCH($A14,Velocity!$T$2:$T$3001,0))) | D14: =IF($A14="","",INDEX(Velocity!$I$2:$I$3001,MATCH($A14,Velocity!$T$2:$T$3001,0))) | E14: =IF($A14="","",IF(INDEX(Velocity!$F$2:$F$3001,MATCH($A14,Velocity!$T$2:$T$3001,0))="","Never",INDEX(Velocity!$F$2:$F$3001,MATCH($A14,Velocity!$T$2:$T$3001,0))))
A15: =IF(8<=$B$4,8,"") | B15: =IF($A15="","",INDEX(Velocity!$A$2:$A$3001,MATCH($A15,Velocity!$T$2:$T$3001,0))) | C15: =IF($A15="","",INDEX(Velocity!$B$2:$B$3001,MATCH($A15,Velocity!$T$2:$T$3001,0))) | D15: =IF($A15="","",INDEX(Velocity!$I$2:$I$3001,MATCH($A15,Velocity!$T$2:$T$3001,0))) | E15: =IF($A15="","",IF(INDEX(Velocity!$F$2:$F$3001,MATCH($A15,Velocity!$T$2:$T$3001,0))="","Never",INDEX(Velocity!$F$2:$F$3001,MATCH($A15,Velocity!$T$2:$T$3001,0))))
A16: =IF(9<=$B$4,9,"") | B16: =IF($A16="","",INDEX(Velocity!$A$2:$A$3001,MATCH($A16,Velocity!$T$2:$T$3001,0))) | C16: =IF($A16="","",INDEX(Velocity!$B$2:$B$3001,MATCH($A16,Velocity!$T$2:$T$3001,0))) | D16: =IF($A16="","",INDEX(Velocity!$I$2:$I$3001,MATCH($A16,Velocity!$T$2:$T$3001,0))) | E16: =IF($A16="","",IF(INDEX(Velocity!$F$2:$F$3001,MATCH($A16,Velocity!$T$2:$T$3001,0))="","Never",INDEX(Velocity!$F$2:$F$3001,MATCH($A16,Velocity!$T$2:$T$3001,0))))
A17: =IF(10<=$B$4,10,"") | B17: =IF($A17="","",INDEX(Velocity!$A$2:$A$3001,MATCH($A17,Velocity!$T$2:$T$3001,0))) | C17: =IF($A17="","",INDEX(Velocity!$B$2:$B$3001,MATCH($A17,Velocity!$T$2:$T$3001,0))) | D17: =IF($A17="","",INDEX(Velocity!$I$2:$I$3001,MATCH($A17,Velocity!$T$2:$T$3001,0))) | E17: =IF($A17="","",IF(INDEX(Velocity!$F$2:$F$3001,MATCH($A17,Velocity!$T$2:$T$3001,0))="","Never",INDEX(Velocity!$F$2:$F$3001,MATCH($A17,Velocity!$T$2:$T$3001,0))))
A18: =IF(11<=$B$4,11,"") | B18: =IF($A18="","",INDEX(Velocity!$A$2:$A$3001,MATCH($A18,Velocity!$T$2:$T$3001,0))) | C18: =IF($A18="","",INDEX(Velocity!$B$2:$B$3001,MATCH($A18,Velocity!$T$2:$T$3001,0))) | D18: =IF($A18="","",INDEX(Velocity!$I$2:$I$3001,MATCH($A18,Velocity!$T$2:$T$3001,0))) | E18: =IF($A18="","",IF(INDEX(Velocity!$F$2:$F$3001,MATCH($A18,Velocity!$T$2:$T$3001,0))="","Never",INDEX(Velocity!$F$2:$F$3001,MATCH($A18,Velocity!$T$2:$T$3001,0))))
A19: =IF(12<=$B$4,12,"") | B19: =IF($A19="","",INDEX(Velocity!$A$2:$A$3001,MATCH($A19,Velocity!$T$2:$T$3001,0))) | C19: =IF($A19="","",INDEX(Velocity!$B$2:$B$3001,MATCH($A19,Velocity!$T$2:$T$3001,0))) | D19: =IF($A19="","",INDEX(Velocity!$I$2:$I$3001,MATCH($A19,Velocity!$T$2:$T$3001,0))) | E19: =IF($A19="","",IF(INDEX(Velocity!$F$2:$F$3001,MATCH($A19,Velocity!$T$2:$T$3001,0))="","Never",INDEX(Velocity!$F$2:$F$3001,MATCH($A19,Velocity!$T$2:$T$3001,0))))
A20: =IF(13<=$B$4,13,"") | B20: =IF($A20="","",INDEX(Velocity!$A$2:$A$3001,MATCH($A20,Velocity!$T$2:$T$3001,0))) | C20: =IF($A20="","",INDEX(Velocity!$B$2:$B$3001,MATCH($A20,Velocity!$T$2:$T$3001,0))) | D20: =IF($A20="","",INDEX(Velocity!$I$2:$I$3001,MATCH($A20,Velocity!$T$2:$T$3001,0))) | E20: =IF($A20="","",IF(INDEX(Velocity!$F$2:$F$3001,MATCH($A20,Velocity!$T$2:$T$3001,0))="","Never",INDEX(Velocity!$F$2:$F$3001,MATCH($A20,Velocity!$T$2:$T$3001,0))))
A21: =IF(14<=$B$4,14,"") | B21: =IF($A21="","",INDEX(Velocity!$A$2:$A$3001,MATCH($A21,Velocity!$T$2:$T$3001,0))) | C21: =IF($A21="","",INDEX(Velocity!$B$2:$B$3001,MATCH($A21,Velocity!$T$2:$T$3001,0))) | D21: =IF($A21="","",INDEX(Velocity!$I$2:$I$3001,MATCH($A21,Velocity!$T$2:$T$3001,0))) | E21: =IF($A21="","",IF(INDEX(Velocity!$F$2:$F$3001,MATCH($A21,Velocity!$T$2:$T$3001,0))="","Never",INDEX(Velocity!$F$2:$F$3001,MATCH($A21,Velocity!$T$2:$T$3001,0))))
A22: =IF(15<=$B$4,15,"") | B22: =IF($A22="","",INDEX(Velocity!$A$2:$A$3001,MATCH($A22,Velocity!$T$2:$T$3001,0))) | C22: =IF($A22="","",INDEX(Velocity!$B$2:$B$3001,MATCH($A22,Velocity!$T$2:$T$3001,0))) | D22: =IF($A22="","",INDEX(Velocity!$I$2:$I$3001,MATCH($A22,Velocity!$T$2:$T$3001,0))) | E22: =IF($A22="","",IF(INDEX(Velocity!$F$2:$F$3001,MATCH($A22,Velocity!$T$2:$T$3001,0))="","Never",INDEX(Velocity!$F$2:$F$3001,MATCH($A22,Velocity!$T$2:$T$3001,0))))
A23: =IF(16<=$B$4,16,"") | B23: =IF($A23="","",INDEX(Velocity!$A$2:$A$3001,MATCH($A23,Velocity!$T$2:$T$3001,0))) | C23: =IF($A23="","",INDEX(Velocity!$B$2:$B$3001,MATCH($A23,Velocity!$T$2:$T$3001,0))) | D23: =IF($A23="","",INDEX(Velocity!$I$2:$I$3001,MATCH($A23,Velocity!$T$2:$T$3001,0))) | E23: =IF($A23="","",IF(INDEX(Velocity!$F$2:$F$3001,MATCH($A23,Velocity!$T$2:$T$3001,0))="","Never",INDEX(Velocity!$F$2:$F$3001,MATCH($A23,Velocity!$T$2:$T$3001,0))))
A24: =IF(17<=$B$4,17,"") | B24: =IF($A24="","",INDEX(Velocity!$A$2:$A$3001,MATCH($A24,Velocity!$T$2:$T$3001,0))) | C24: =IF($A24="","",INDEX(Velocity!$B$2:$B$3001,MATCH($A24,Velocity!$T$2:$T$3001,0))) | D24: =IF($A24="","",INDEX(Velocity!$I$2:$I$3001,MATCH($A24,Velocity!$T$2:$T$3001,0))) | E24: =IF($A24="","",IF(INDEX(Velocity!$F$2:$F$3001,MATCH($A24,Velocity!$T$2:$T$3001,0))="","Never",INDEX(Velocity!$F$2:$F$3001,MATCH($A24,Velocity!$T$2:$T$3001,0))))
A25: =IF(18<=$B$4,18,"") | B25: =IF($A25="","",INDEX(Velocity!$A$2:$A$3001,MATCH($A25,Velocity!$T$2:$T$3001,0))) | C25: =IF($A25="","",INDEX(Velocity!$B$2:$B$3001,MATCH($A25,Velocity!$T$2:$T$3001,0))) | D25: =IF($A25="","",INDEX(Velocity!$I$2:$I$3001,MATCH($A25,Velocity!$T$2:$T$3001,0))) | E25: =IF($A25="","",IF(INDEX(Velocity!$F$2:$F$3001,MATCH($A25,Velocity!$T$2:$T$3001,0))="","Never",INDEX(Velocity!$F$2:$F$3001,MATCH($A25,Velocity!$T$2:$T$3001,0))))
A26: =IF(19<=$B$4,19,"") | B26: =IF($A26="","",INDEX(Velocity!$A$2:$A$3001,MATCH($A26,Velocity!$T$2:$T$3001,0))) | C26: =IF($A26="","",INDEX(Velocity!$B$2:$B$3001,MATCH($A26,Velocity!$T$2:$T$3001,0))) | D26: =IF($A26="","",INDEX(Velocity!$I$2:$I$3001,MATCH($A26,Velocity!$T$2:$T$3001,0))) | E26: =IF($A26="","",IF(INDEX(Velocity!$F$2:$F$3001,MATCH($A26,Velocity!$T$2:$T$3001,0))="","Never",INDEX(Velocity!$F$2:$F$3001,MATCH($A26,Velocity!$T$2:$T$3001,0))))
A27: =IF(20<=$B$4,20,"") | B27: =IF($A27="","",INDEX(Velocity!$A$2:$A$3001,MATCH($A27,Velocity!$T$2:$T$3001,0))) | C27: =IF($A27="","",INDEX(Velocity!$B$2:$B$3001,MATCH($A27,Velocity!$T$2:$T$3001,0))) | D27: =IF($A27="","",INDEX(Velocity!$I$2:$I$3001,MATCH($A27,Velocity!$T$2:$T$3001,0))) | E27: =IF($A27="","",IF(INDEX(Velocity!$F$2:$F$3001,MATCH($A27,Velocity!$T$2:$T$3001,0))="","Never",INDEX(Velocity!$F$2:$F$3001,MATCH($A27,Velocity!$T$2:$T$3001,0))))
A28: =IF(21<=$B$4,21,"") | B28: =IF($A28="","",INDEX(Velocity!$A$2:$A$3001,MATCH($A28,Velocity!$T$2:$T$3001,0))) | C28: =IF($A28="","",INDEX(Velocity!$B$2:$B$3001,MATCH($A28,Velocity!$T$2:$T$3001,0))) | D28: =IF($A28="","",INDEX(Velocity!$I$2:$I$3001,MATCH($A28,Velocity!$T$2:$T$3001,0))) | E28: =IF($A28="","",IF(INDEX(Velocity!$F$2:$F$3001,MATCH($A28,Velocity!$T$2:$T$3001,0))="","Never",INDEX(Velocity!$F$2:$F$3001,MATCH($A28,Velocity!$T$2:$T$3001,0))))
A29: =IF(22<=$B$4,22,"") | B29: =IF($A29="","",INDEX(Velocity!$A$2:$A$3001,MATCH($A29,Velocity!$T$2:$T$3001,0))) | C29: =IF($A29="","",INDEX(Velocity!$B$2:$B$3001,MATCH($A29,Velocity!$T$2:$T$3001,0))) | D29: =IF($A29="","",INDEX(Velocity!$I$2:$I$3001,MATCH($A29,Velocity!$T$2:$T$3001,0))) | E29: =IF($A29="","",IF(INDEX(Velocity!$F$2:$F$3001,MATCH($A29,Velocity!$T$2:$T$3001,0))="","Never",INDEX(Velocity!$F$2:$F$3001,MATCH($A29,Velocity!$T$2:$T$3001,0))))
A30: =IF(23<=$B$4,23,"") | B30: =IF($A30="","",INDEX(Velocity!$A$2:$A$3001,MATCH($A30,Velocity!$T$2:$T$3001,0))) | C30: =IF($A30="","",INDEX(Velocity!$B$2:$B$3001,MATCH($A30,Velocity!$T$2:$T$3001,0))) | D30: =IF($A30="","",INDEX(Velocity!$I$2:$I$3001,MATCH($A30,Velocity!$T$2:$T$3001,0))) | E30: =IF($A30="","",IF(INDEX(Velocity!$F$2:$F$3001,MATCH($A30,Velocity!$T$2:$T$3001,0))="","Never",INDEX(Velocity!$F$2:$F$3001,MATCH($A30,Velocity!$T$2:$T$3001,0))))
A31: =IF(24<=$B$4,24,"") | B31: =IF($A31="","",INDEX(Velocity!$A$2:$A$3001,MATCH($A31,Velocity!$T$2:$T$3001,0))) | C31: =IF($A31="","",INDEX(Velocity!$B$2:$B$3001,MATCH($A31,Velocity!$T$2:$T$3001,0))) | D31: =IF($A31="","",INDEX(Velocity!$I$2:$I$3001,MATCH($A31,Velocity!$T$2:$T$3001,0))) | E31: =IF($A31="","",IF(INDEX(Velocity!$F$2:$F$3001,MATCH($A31,Velocity!$T$2:$T$3001,0))="","Never",INDEX(Velocity!$F$2:$F$3001,MATCH($A31,Velocity!$T$2:$T$3001,0))))
A32: =IF(25<=$B$4,25,"") | B32: =IF($A32="","",INDEX(Velocity!$A$2:$A$3001,MATCH($A32,Velocity!$T$2:$T$3001,0))) | C32: =IF($A32="","",INDEX(Velocity!$B$2:$B$3001,MATCH($A32,Velocity!$T$2:$T$3001,0))) | D32: =IF($A32="","",INDEX(Velocity!$I$2:$I$3001,MATCH($A32,Velocity!$T$2:$T$3001,0))) | E32: =IF($A32="","",IF(INDEX(Velocity!$F$2:$F$3001,MATCH($A32,Velocity!$T$2:$T$3001,0))="","Never",INDEX(Velocity!$F$2:$F$3001,MATCH($A32,Velocity!$T$2:$T$3001,0))))
A33: =IF(26<=$B$4,26,"") | B33: =IF($A33="","",INDEX(Velocity!$A$2:$A$3001,MATCH($A33,Velocity!$T$2:$T$3001,0))) | C33: =IF($A33="","",INDEX(Velocity!$B$2:$B$3001,MATCH($A33,Velocity!$T$2:$T$3001,0))) | D33: =IF($A33="","",INDEX(Velocity!$I$2:$I$3001,MATCH($A33,Velocity!$T$2:$T$3001,0))) | E33: =IF($A33="","",IF(INDEX(Velocity!$F$2:$F$3001,MATCH($A33,Velocity!$T$2:$T$3001,0))="","Never",INDEX(Velocity!$F$2:$F$3001,MATCH($A33,Velocity!$T$2:$T$3001,0))))
A34: =IF(27<=$B$4,27,"") | B34: =IF($A34="","",INDEX(Velocity!$A$2:$A$3001,MATCH($A34,Velocity!$T$2:$T$3001,0))) | C34: =IF($A34="","",INDEX(Velocity!$B$2:$B$3001,MATCH($A34,Velocity!$T$2:$T$3001,0))) | D34: =IF($A34="","",INDEX(Velocity!$I$2:$I$3001,MATCH($A34,Velocity!$T$2:$T$3001,0))) | E34: =IF($A34="","",IF(INDEX(Velocity!$F$2:$F$3001,MATCH($A34,Velocity!$T$2:$T$3001,0))="","Never",INDEX(Velocity!$F$2:$F$3001,MATCH($A34,Velocity!$T$2:$T$3001,0))))
A35: =IF(28<=$B$4,28,"") | B35: =IF($A35="","",INDEX(Velocity!$A$2:$A$3001,MATCH($A35,Velocity!$T$2:$T$3001,0))) | C35: =IF($A35="","",INDEX(Velocity!$B$2:$B$3001,MATCH($A35,Velocity!$T$2:$T$3001,0))) | D35: =IF($A35="","",INDEX(Velocity!$I$2:$I$3001,MATCH($A35,Velocity!$T$2:$T$3001,0))) | E35: =IF($A35="","",IF(INDEX(Velocity!$F$2:$F$3001,MATCH($A35,Velocity!$T$2:$T$3001,0))="","Never",INDEX(Velocity!$F$2:$F$3001,MATCH($A35,Velocity!$T$2:$T$3001,0))))
A36: =IF(29<=$B$4,29,"") | B36: =IF($A36="","",INDEX(Velocity!$A$2:$A$3001,MATCH($A36,Velocity!$T$2:$T$3001,0))) | C36: =IF($A36="","",INDEX(Velocity!$B$2:$B$3001,MATCH($A36,Velocity!$T$2:$T$3001,0))) | D36: =IF($A36="","",INDEX(Velocity!$I$2:$I$3001,MATCH($A36,Velocity!$T$2:$T$3001,0))) | E36: =IF($A36="","",IF(INDEX(Velocity!$F$2:$F$3001,MATCH($A36,Velocity!$T$2:$T$3001,0))="","Never",INDEX(Velocity!$F$2:$F$3001,MATCH($A36,Velocity!$T$2:$T$3001,0))))
A37: =IF(30<=$B$4,30,"") | B37: =IF($A37="","",INDEX(Velocity!$A$2:$A$3001,MATCH($A37,Velocity!$T$2:$T$3001,0))) | C37: =IF($A37="","",INDEX(Velocity!$B$2:$B$3001,MATCH($A37,Velocity!$T$2:$T$3001,0))) | D37: =IF($A37="","",INDEX(Velocity!$I$2:$I$3001,MATCH($A37,Velocity!$T$2:$T$3001,0))) | E37: =IF($A37="","",IF(INDEX(Velocity!$F$2:$F$3001,MATCH($A37,Velocity!$T$2:$T$3001,0))="","Never",INDEX(Velocity!$F$2:$F$3001,MATCH($A37,Velocity!$T$2:$T$3001,0))))
A38: =IF(31<=$B$4,31,"") | B38: =IF($A38="","",INDEX(Velocity!$A$2:$A$3001,MATCH($A38,Velocity!$T$2:$T$3001,0))) | C38: =IF($A38="","",INDEX(Velocity!$B$2:$B$3001,MATCH($A38,Velocity!$T$2:$T$3001,0))) | D38: =IF($A38="","",INDEX(Velocity!$I$2:$I$3001,MATCH($A38,Velocity!$T$2:$T$3001,0))) | E38: =IF($A38="","",IF(INDEX(Velocity!$F$2:$F$3001,MATCH($A38,Velocity!$T$2:$T$3001,0))="","Never",INDEX(Velocity!$F$2:$F$3001,MATCH($A38,Velocity!$T$2:$T$3001,0))))
